Workbook
Name SOFR: '01_Params'!$D$5
Name TSOFR1M: '01_Params'!$D$6
Name TSOFR3M: '01_Params'!$D$7
Name CD91D: '01_Params'!$D$8
Name BOK_Base: '01_Params'!$D$9
Name USDKRW: '01_Params'!$D$10
Name Hana31: '01_Params'!$D$11
Name Hana92: '01_Params'!$D$12
Name Hana184: '01_Params'!$D$13
Name ImplSpread31: '01_Params'!$D$14
Name ImplSpread92: '01_Params'!$D$15
Name DayBasis: '01_Params'!$D$16
Name DayBasisKRW: '01_Params'!$D$17
Name Fee_KRW: '01_Params'!$D$18
Name CollectFee: '01_Params'!$D$19
Name FactoringFee: '01_Params'!$D$20
Name KS_Direct_AC: '01_Params'!$D$21
Name KS_Direct_Oth: '01_Params'!$D$22
Name KS_Direct_Gen: '01_Params'!$D$23
Name KS_PlusLo: '01_Params'!$D$24
Name KS_PlusHi: '01_Params'!$D$25
Name KS_PlusLC: '01_Params'!$D$26
Name KS_Forfaiting: '01_Params'!$D$27
Name KS_GuarLo: '01_Params'!$D$28
Name KS_GuarHi: '01_Params'!$D$29
Name Cov: '01_Params'!$D$30
Name Spread_S: '01_Params'!$D$31
Name Spread_A: '01_Params'!$D$32
Name Spread_B: '01_Params'!$D$33
Name Spread_C: '01_Params'!$D$34
Name Prem_S: '01_Params'!$D$35
Name Prem_A: '01_Params'!$D$36
Name Prem_B: '01_Params'!$D$37
Name Prem_C: '01_Params'!$D$38
Name PD_S: '01_Params'!$D$39
Name PD_A: '01_Params'!$D$40
Name PD_B: '01_Params'!$D$41
Name PD_C: '01_Params'!$D$42
Name LGD: '01_Params'!$D$43
Name EarlyPay_2_10_30: '01_Params'!$D$44
Name Equity_USD: '01_Params'!$D$45
Name Alpha: '01_Params'!$D$46
Name s_S: '01_Params'!$D$47
Name s_A: '01_Params'!$D$48
Name s_B: '01_Params'!$D$49
Name s_C: '01_Params'!$D$50
Name Fed_Lo: '01_Params'!$D$51
Name Fed_Hi: '01_Params'!$D$52
Name Tenor: '01_Params'!$D$53
Name Grace: '01_Params'!$D$54
Name Cap_A: '01_Params'!$D$55
Name Cap_B: '01_Params'!$D$56
Name Cap_C_OA: '01_Params'!$D$57
Name ShareCap_B: '01_Params'!$D$58
Name CtryCap_02: '01_Params'!$D$59
Name CtryCap_3: '01_Params'!$D$60
Name CtryCap_45: '01_Params'!$D$61
Name CtryCap_67: '01_Params'!$D$62
Name TotalCapShare: '01_Params'!$D$63
Name Util: '01_Params'!$D$64

Sheet 00_README
A1: d4_limit_model.xlsx — Day4 한도 최적화·할인율·시나리오·조기경보 워크북 (가상 한빛정밀(주) 교육용)
A3: 파일 | B3: 빈 틀(공개 저장소 labs/day4) — 02_Buyers에 d4_start_scored.csv를 붙여 넣어 시작
A4: 목적 | B4: 등급(PD)·보험·금융비용을 반영해 바이어별 신용한도를 선형계획(LP)으로 배분하고, 할인율·NPV, 4단계 충격·몬테카를로, 충당금, 조기경보를 한 파일에서 계산한다.
A5: 기준일 | B5: 2026-09-30(01_Params AsOf) · 금리 2026-09-23(Term SOFR 3M 4.047%, 하나은행 환가료) · 원/달러 1,360.0(ECOS 매매기준율 09-23)
A6: 색 규칙 | B6: 파랑 = 공시·규정값 · 노랑 = [가정]·[교육용 가정](바꿔 볼 수 있음) · 회색 = 수식(수정 금지) · 주황 = 결정변수(해 찾기가 채움) · 연두 = 붙여넣기 칸
A7: 시작(Lab 1) | B7: ① 01_Params 노랑 칸 확인 ② d4_start_scored.csv 전체(머리글 포함)를 복사 → 02_Buyers A1에 '값 붙여넣기'(Ctrl+Alt+V → 값) — 회색 열이 150행 채워지는지 확인 ③ 03_RateBuild 검산표 ✔ ④ 05_NPV 은행 견적 1,669.54달러·6.59%
A8: 한도 LP(Lab 2) | B8: 10_LimitLP → 데이터 → 해 찾기: 목표 $C$2(Obj) 최대 · 변수 $F$5:$F$154 · 제약 6줄(시트 오른쪽 '해 찾기 입력표') · '제한되지 않는 변수를 음이 아닌 수로' ✔ · 해법 '단순 LP' → 해 찾기 → 보고서 '해답'·'민감도'
A9: 해 찾기 켜기 | B9: 파일 → 옵션 → 추가 기능 → 관리: Excel 추가 기능 → 이동 → '해 찾기 추가 기능' ✔. 웹 Excel에는 없다(Frontline Solver App·Google Sheets+OpenSolver)
A10: 시나리오(Lab 3) | B10: 11_Scenario: S0~S4 결과표 · 실제 충격 재현(R2026) · 몬테카를로(드롭다운에서 시나리오 선택 → F9). 계산 옵션은 '데이터 표를 제외하고 자동'으로 저장돼 있다 — 데이터 표 1,000회는 F9를 눌러야 갱신
A11: 조기경보 | B11: 13_EarlyWarning: open_inv(기준일 미결 인보이스 ≤300행) → 단계(D-3/D+7/D+15/D+30)·K-SURE 사고발생통지 기한(결제기일 + 1개월)·선적 보류. 선적 보류 바이어는 02_Buyers UB가 0이 된다
A12: 리포트(Lab 4) | B12: 14_ReportInput 표 5개 → 프롬프트 P4-1(바이어 실명 없이 ID만). 한도 변경·선적 보류·K-SURE 통지는 사람이 승인한다
A13: 🔵 선택 | B13: 06_WeeklyGap·07_Solver(유동성 갭 최소비용 매각) · 08_Sensitivity · 12_ECL(충당금 3종) · 15_Bond(공공조달 보증 EAD) · 01_Params GradeRule = quantile(분위수 등급 비교)
A14: 🟣 Challenge | B14: labs/day4/d4_challenge.ipynb(PuLP 3.3.2 · scipy linprog · 몬테카를로 1-요인) → 16_Compare에 PuLP 해를 붙여 비교
... A18: 데이터 | B18: (가상) 한빛정밀(주) 합성 데이터 — 실존 기업·인물과 무관. 회사 실데이터는 익명화 템플릿을 거친 뒤에만 넣는다
A20: 색 견본 | B20: 공시·규정 | C20: 가정 | D20: 수식 | E20: 결정변수 | F20: 붙여넣기
A22: 시트 | B22: 내용
A23: 00_README | B23: 이 안내
A24: 01_Params | B24: 파라미터 65개(이름 정의) + AsOf·GradeRule 등
A25: 02_Buyers | B25: d4_start_scored 붙여넣기(A~AI) + 계산 열(AK~BI): PD·r·Need·Cap·Ins·Self·UB·LB·coef
A26: 03_RateBuild | B26: 등급별 위험조정 할인율·NPV 검산(USD 100,000·90일)
A27: 04_AR_Ledger | B27: G03 예제 원장 R1~R7(🔵)
A28: 05_NPV | B28: 은행 견적 대조 + 바이어별 채권 NPV·부보 판정
A29: 06_WeeklyGap | B29: 8주 유동성 갭(🔵)
A30: 07_Solver | B30: 최소비용 매각 LP(🔵, 해 찾기 모델 저장됨)
A31: 08_Sensitivity | B31: TSOFR ±100bp·PD×2·LGD 40/80%
A32: 09_Chart | B32: 누적현금·할인율 구성·등급별 한도 차트
A33: 10_LimitLP | B33: 한도 배분 LP(해 찾기 모델 저장됨) + 국가 한도 블록
... A39: 16_Compare | B39: Excel vs PuLP(🟣)

Sheet 01_Params
A1: 01_Params — 파라미터(셀마다 이름 정의, d4_params.csv와 같은 값)
A2: 값은 소수로 넣는다(4.047% = 0.04047, 백분율 서식). 파랑 = 공시·규정 · 노랑 = [가정]·[교육용 가정](🔵 바꿔 보기) · 회색 = 계산
A4: param_id | B4: 이름(Excel) | C4: 항목 | D4: 값 | E4: 단위 | F4: 구분 | G4: 출처 | H4: 기준일 | I4: 메모 | J4: URL
A5: P1 | B5: SOFR | C5: SOFR(익일물 담보 기준금리) | D5: 0.0388 | E5: 연율 | F5: 확인 | G5: NY Fed SOFR API [G03 1] | H5: 2026-09-24 | I5: 09-16 3.62% → 09-17 3.85%(FOMC 인상 다음 날) | J5: https://markets.newyorkfed.org/api/rates/secured/sofr/last/10.json
A6: P2 | B6: TSOFR1M | C6: Term SOFR 1개월 | D6: 0.03901 | E6: 연율 | F6: 확인 | G6: CME Term SOFR(Chatham 재배포) [G03 5] | H6: 2026-09-23 | I6: CME 원 페이지는 자동 조회 차단 — 수업 당일 브라우저로 확인 | J6: https://cf.com/rates/us
A7: P3 | B7: TSOFR3M | C7: Term SOFR 3개월 | D7: 0.04047 | E7: 연율 | F7: 확인 | G7: CME Term SOFR(Chatham 재배포) [G03 5] | H7: 2026-09-23 | I7: 할인율·LP 금리의 기준 B(t) | J7: https://cf.com/rates/us
A8: P4 | B8: CD91D | C8: CD 91일물 | D8: 0.0321 | E8: 연율 | F8: 확인 | G8: 한국은행 ECOS 817Y002/010502000 [G03 7] | H8: 2026-09-23 | I8: 원화 대안 비교용 | J8: https://ecos.bok.or.kr/
A9: P5 | B9: BOK_Base | C9: 한국은행 기준금리 | D9: 0.03 | E9: 연율 | F9: 확인 | G9: 한국은행 기준금리 추이 [G03 6] | H9: 2026-08-27 | I9: 2.50%(2025-05-29) → 2.75%(2026-07-16) → 3.00%(2026-08-27 인상) | J9: https://www.bok.or.kr/portal/singl/baseRate/list.do?dataSeCd=01&menuNo=200643
A10: P6 | B10: USDKRW | C10: 원/달러 매매기준율 | D10: 1360 | E10: 원 | F10: 확인 | G10: 한국은행 ECOS 731Y001/0000001 [G03 9] | H10: 2026-09-23 | I10: FRED 뉴욕 정오율과 기준·시각이 다르다 — 11_Scenario S0 원/달러 | J10: https://ecos.bok.or.kr/
A11: P7_31D | B11: Hana31 | C11: 하나은행 USD 기한부 환가료율 31일(일괄선취) | D11: 0.0574851 | E11: 연율 | F11: 확인 | G11: 하나은행 기한부환가료율 [G03 10] | H11: 2026-09-23 | I11: 고시 = 기준금리(Term SOFR) + 가산금리, 우대 전 | J11: https://www.kebhana.com/cms/rate/index.do?contentUrl=/cms/rate/wpfxd652_01i.do
A12: P7_92D | B12: Hana92 | C12: 하나은행 USD 기한부 환가료율 92일(일괄선취) | D12: 0.0653297 | E12: 연율 | F12: 확인 | G12: 하나은행 기한부환가료율 [G03 10] | H12: 2026-09-23 | I12: 05_NPV 은행 견적 대조(USD 100,000·92일 → 환가료 USD 1,669.54) | J12: https://www.kebhana.com/cms/rate/index.do?contentUrl=/cms/rate/wpfxd652_01i.do
A13: P7_184D | B13: Hana184 | C13: 하나은행 USD 기한부 환가료율 184일(일괄선취) | D13: 0.0690141 | E13: 연율 | F13: 확인 | G13: 하나은행 기한부환가료율 [G03 10] | H13: 2026-09-23 | I13: 123·184일 같은 구간 | J13: https://www.kebhana.com/cms/rate/index.do?contentUrl=/cms/rate/wpfxd652_01i.do
A14: P8_31D | B14: ImplSpread31 | C14: 암묵 가산금리 31일(고시 − Term SOFR 1M) | D14: =Hana31-TSOFR1M | E14: %p | F14: 계산 | G14: P7_31D − P2 [G03 §2.2.3] | H14: 2026-09-23 | I14: 우대 전 고시 기준 상한 성격
A15: P8_92D | B15: ImplSpread92 | C15: 암묵 가산금리 92일(고시 − Term SOFR 3M) | D15: =Hana92-TSOFR3M | E15: %p | F15: 계산 | G15: P7_92D − P3 [G03 §2.2.3] | H15: 2026-09-23 | I15: C등급 은행 가산(P19_C 2.5%p)의 상한 근거
A16: P9_USD | B16: DayBasis | C16: 일수 기준(USD) | D16: 360 | E16: 일 | F16: 확인 | G16: 하나은행 환가료 공시 [G03 10] | H16: 2026-09-23 | I16: KRW·GBP·JPY 등은 365 | J16: https://www.kebhana.com/cms/rate/index.do?contentUrl=/cms/rate/wpfxd652_01i.do
A17: P9_KRW | B17: DayBasisKRW | C17: 일수 기준(KRW) | D17: 365 | E17: 일 | F17: 확인 | G17: 하나은행 환가료 공시 [G03 10] | H17: 2026-09-23 | J17: https://www.kebhana.com/cms/rate/index.do?contentUrl=/cms/rate/wpfxd652_01i.do
A18: P10 | B18: Fee_KRW | C18: 수출환어음 매입취급수수료 | D18: 20000 | E18: 원/건 | F18: 확인 | G18: 은행연합회 수출입수수료 비교공시 [G03 14] | H18: 2026-09-26 | I18: 하나·우리·KB(외화) 2만 원, IBK 면제 | J18: https://portal.kfb.or.kr/compare/commission_exchange_2.php
A19: P11 | B19: CollectFee | C19: 수출환어음 추심수수료 | D19: 0.001 | E19: 건당 비율 | F19: 확인 | G19: 은행연합회 수출입수수료 비교공시 [G03 14] | H19: 2026-09-26 | I19: 최저 1~2만·최고 3만 원(하나는 건당 2만 원) | J19: https://portal.kfb.or.kr/compare/commission_exchange_2.php
A20: P12 | B20: FactoringFee | C20: 국제팩토링 취급수수료(IBK) | D20: 0.004 | E20: 건당 비율 | F20: 확인 | G20: IBK 수출입 이용수수료 [G03 16] | H20: 2026-06-01 | I20: 추심 0.2%, 신용조회 건당 1만 원 | J20: https://www.ibk.co.kr/inform/detailFee.ibk?category=E&pageId=FM04010200
A21: P13_AC | B21: KS_Direct_AC | C21: K-SURE 다이렉트 선적후 수입자 지정형 A~C급 요율 | D21: 0.004 | E21: 건당 비율 | F21: 확인 | G21: 무역보험 제도안내 2026.8 PDF 23쪽 [G03 19] | H21: 2026-09-09 | I21: 수입자별 U$20만, 보상비율 95% | J21: https://www.ksure.or.kr/rh-kr/bbs/i-329/down.do?bbs_id=1014&atfile_sn=1&data_ty_cd=A&ntt_sn=38033
A22: P13_OTH | B22: KS_Direct_Oth | C22: K-SURE 다이렉트 선적후 수입자 지정형 그 외 등급 요율 | D22: 0.005 | E22: 건당 비율 | F22: 확인 | G22: 무역보험 제도안내 2026.8 PDF 23쪽 [G03 19] | H22: 2026-09-09 | I22: 수입자별 U$10만 | J22: https://www.ksure.or.kr/rh-kr/bbs/i-329/down.do?bbs_id=1014&atfile_sn=1&data_ty_cd=A&ntt_sn=38033
A23: P13_GEN | B23: KS_Direct_Gen | C23: K-SURE 다이렉트 선적후 일반형 요율 | D23: 0.006 | E23: 건당 비율 | F23: 확인 | G23: 무역보험 제도안내 2026.8 PDF 23쪽 [G03 19] | H23: 2026-09-09 | I23: 건별 U$5만·수출자별 U$10만 | J23: https://www.ksure.or.kr/rh-kr/bbs/i-329/down.do?bbs_id=1014&atfile_sn=1&data_ty_cd=A&ntt_sn=38033
A24: P14_LO | B24: KS_PlusLo | C24: K-SURE 중소중견Plus+ 무신용장(중소) 하한 | D24: 0.0082 | E24: 연율 | F24: 확인 | G24: 무역보험 제도안내 2026.8 PDF 26쪽 [G03 19] | H24: 2026-09-09 | I24: 책임금액 구간별 누진 | J24: https://www.ksure.or.kr/rh-kr/bbs/i-329/down.do?bbs_id=1014&atfile_sn=1&data_ty_cd=A&ntt_sn=38033
A25: P14_HI | B25: KS_PlusHi | C25: K-SURE 중소중견Plus+ 무신용장(중소) 상한 | D25: 0.0162 | E25: 연율 | F25: 확인 | G25: 무역보험 제도안내 2026.8 PDF 26쪽 [G03 19] | H25: 2026-09-09 | I25: 중견 1.020~2.520% | J25: https://www.ksure.or.kr/rh-kr/bbs/i-329/down.do?bbs_id=1014&atfile_sn=1&data_ty_cd=A&ntt_sn=38033
A26: P15 | B26: KS_PlusLC | C26: K-SURE 중소중견Plus+ 신용장 | D26: 0.0022 | E26: 연율 | F26: 확인 | G26: 무역보험 제도안내 2026.8 PDF 26쪽 [G03 19] | H26: 2026-09-09 | J26: https://www.ksure.or.kr/rh-kr/bbs/i-329/down.do?bbs_id=1014&atfile_sn=1&data_ty_cd=A&ntt_sn=38033
A27: P16 | B27: KS_Forfaiting | C27: 포페이팅 보험 | D27: 0.004 | E27: 연율 | F27: 확인 | G27: 무역보험 제도안내 2026.8 PDF 33쪽 [G03 19] | H27: 2026-09-09 | I27: 국가등급이 높을수록·개설은행 순자산이 클수록 저렴 | J27: https://www.ksure.or.kr/rh-kr/bbs/i-329/down.do?bbs_id=1014&atfile_sn=1&data_ty_cd=A&ntt_sn=38033
A28: P17_LO | B28: KS_GuarLo | C28: 수출신용보증(매입) 하한 | D28: 0.005 | E28: 연율 | F28: 확인 | G28: 무역보험 제도안내 2026.8 PDF 46쪽 [G03 19] | H28: 2026-09-09 | I28: 포괄매입 0.25~0.85%(48쪽) | J28: https://www.ksure.or.kr/rh-kr/bbs/i-329/down.do?bbs_id=1014&atfile_sn=1&data_ty_cd=A&ntt_sn=38033
A29: P17_HI | B29: KS_GuarHi | C29: 수출신용보증(매입) 상한 | D29: 0.025 | E29: 연율 | F29: 확인 | G29: 무역보험 제도안내 2026.8 PDF 46쪽 [G03 19] | H29: 2026-09-09 | J29: https://www.ksure.or.kr/rh-kr/bbs/i-329/down.do?bbs_id=1014&atfile_sn=1&data_ty_cd=A&ntt_sn=38033
A30: P18 | B30: Cov | C30: 보상비율(다이렉트 선적후) | D30: 0.95 | E30: 비율 | F30: 확인 | G30: 무역보험 제도안내 2026.8 PDF 23쪽 [G03 19] | H30: 2026-09-09 | I30: 단기수출보험 중소기업 부보율은 100% — 실습은 보수적으로 95% | J30: https://www.ksure.or.kr/rh-kr/bbs/i-329/down.do?bbs_id=1014&atfile_sn=1&data_ty_cd=A&ntt_sn=38033
A31: P19_S | B31: Spread_S | C31: 은행 가산금리 S | D31: 0.01 | E31: %p | F31: 가정 | G31: G03 P19 [가정] | I31: C는 P8 92일(2.49%p) 상한
A32: P19_A | B32: Spread_A | C32: 은행 가산금리 A | D32: 0.015 | E32: %p | F32: 가정 | G32: G03 P19 [가정]
A33: P19_B | B33: Spread_B | C33: 은행 가산금리 B | D33: 0.02 | E33: %p | F33: 가정 | G33: G03 P19 [가정]
A34: P19_C | B34: Spread_C | C34: 은행 가산금리 C | D34: 0.025 | E34: %p | F34: 가정 | G34: G03 P19 [가정]
A35: P20_S | B35: Prem_S | C35: K-SURE 보험료 S(90일 건당) | D35: 0.003 | E35: 건당 비율 | F35: 가정 | G35: G03 P20 [가정] — 요율표 비공개, P13~P15 앵커 | I35: 연환산 = 요율 × 365 ÷ 결제기간
A36: P20_A | B36: Prem_A | C36: K-SURE 보험료 A(90일 건당) | D36: 0.004 | E36: 건당 비율 | F36: 가정 | G36: G03 P20 [가정]
A37: P20_B | B37: Prem_B | C37: K-SURE 보험료 B(90일 건당) | D37: 0.005 | E37: 건당 비율 | F37: 가정 | G37: G03 P20 [가정]
A38: P20_C | B38: Prem_C | C38: K-SURE 보험료 C(90일 건당) | D38: 0.01 | E38: 건당 비율 | F38: 가정 | G38: G03 P20 [가정]
A39: P21_S | B39: PD_S | C39: 연 부도확률 S | D39: 0.005 | E39: 연율 | F39: 가정 | G39: G03 P21 [가정] — ICC 무역금융 부도율 참조
A40: P21_A | B40: PD_A | C40: 연 부도확률 A | D40: 0.015 | E40: 연율 | F40: 가정 | G40: G03 P21 [가정]
A41: P21_B | B41: PD_B | C41: 연 부도확률 B | D41: 0.04 | E41: 연율 | F41: 가정 | G41: G03 P21 [가정]
...

Sheet 02_Buyers
A1: buyer_id | B1: ref_date | C1: pd_30d | D1: pred_late | E1: threshold_used | F1: grade | G1: grade_rule | H1: rank_pct | I1: grade_quantile | J1: top_feature_1 | K1: top_contrib_1 | L1: top_feature_2 | M1: top_contrib_2 | N1: top_feature_3 | O1: top_contrib_3 | P1: top_reasons_ko | Q1: model_version | R1: buyer_name | S1: country_code | T1: currency | U1: payment_method | V1: terms_days | W1: ksure_insured | X1: ksure_limit_usd | Y1: monthly_sales_usd | Z1: open_ar_usd | AA1: overdue_amount_usd | AB1: current_limit_usd | AC1: oecd_crc | AD1: pd_annual_assumed | AE1: lgd_assumed | AF1: coverage_ratio | AG1: strategic_flag | AH1: bankruptcy_flag | AI1: buyer_type | AJ1: ▶ 계산 | AK1: grade_used | AL1: PD_g | AM1: PD_eff | AN1: LGD_i | AO1: cov_i | AP1: spread_g | AQ1: prem_g | AR1: r_unins | AS1: r_ins | AT1: r_i | AU1: ins_decision | AV1: need | AW1: cap | AX1: ins | AY1: self | AZ1: ship_hold | BA1: limit_scope | BB1: UB | BC1: LB | BD1: coef | BE1: elc | BF1: crc_band | BG1: el_now | BH1: fin_cost_now | BI1: risk_key
AK2: =IF($A2="","",IF(GradeRule="quantile",$I2,$F2)) | AL2: =IF($A2="","",CHOOSE(MATCH($AK2,{"S","A","B","C"},0),PD_S,PD_A,PD_B,PD_C)) | AM2: =IF($A2="","",IF($AH2=1,1,$AL2)) | AN2: =IF($A2="","",IF(OR($U2="LC_SIGHT",$U2="LC_USANCE"),LGD_LC,LGD)) | AO2: =IF($A2="","",IF($W2="Y",Cov,0)) | AP2: =IF($A2="","",CHOOSE(MATCH($AK2,{"S","A","B","C"},0),Spread_S,Spread_A,Spread_B,Spread_C)) | AQ2: =IF($A2="","",CHOOSE(MATCH($AK2,{"S","A","B","C"},0),Prem_S,Prem_A,Prem_B,Prem_C)) | AR2: =IF(OR($A2="",$V2<=0),"",TSOFR3M+$AP2+$AL2*$AN2) | AS2: =IF(OR($A2="",$V2<=0),"",TSOFR3M+$AP2+$AQ2*365/$V2+$AL2*$AN2*(1-Cov)) | AT2: =IF(OR($A2="",$V2<=0),"",IF($W2="Y",$AS2,$AR2)) | AU2: =IF(OR($A2="",$V2<=0),"",IF($AS2<$AR2,"부보 유리","무보험 유리")) | AV2: =IF($A2="","",$Y2*($V2+Grace)/30) | AW2: =IF($A2="","",CHOOSE(MATCH($AK2,{"S","A","B","C"},0),$AV2,Cap_A,Cap_B,Cap_C_OA)) | AX2: =IF($A2="","",IF($W2="Y",$X2,0)) | AY2: =IF($A2="","",Equity_USD*CHOOSE(MATCH($AK2,{"S","A","B","C"},0),s_S,s_A,s_B,s_C)) | AZ2: =IF($A2="","",'13_EarlyWarning'!$AH5) | BA2: =IF($A2="","",IF(OR($U2="LC_SIGHT",$U2="LC_USANCE",$U2="TT_ADV"),"대상 아님","대상")) | BB2: =IF($A2="","",IF(OR($BA2="대상 아님",$AZ2<>"",$AH2=1),0,MIN($AV2,$AW2,$AX2+$AY2))) | BC2: =IF($A2="","",IF($AG2=1,MIN(StratMin*$AB2,$BB2),0)) | BD2: =IF($A2="","",IF(OR($V2<=0,$BB2<=0),0,Util*(GM*365/$V2-$AT2))) | BE2: =IF($A2="","",Util*$AL2*$AN2*(1-$AO2)) | BF2: =IF($A2="","",IF($AC2="","0-2",IF($AC2<=2,"0-2",IF($AC2=3,"3",IF($AC2<=5,"4-5","6-7"))))) | BG2: =IF($A2="","",$Z2*$AM2*$AN2*(1-$AO2)) | BH2: =IF($A2="","",$Z2*(TSOFR3M+$AP2)*$V2/DayBasis) | BI2: =IF($A2="","",$C2+$Z2*1E-13)
AK3: =IF($A3="","",IF(GradeRule="quantile",$I3,$F3)) | AL3: =IF($A3="","",CHOOSE(MATCH($AK3,{"S","A","B","C"},0),PD_S,PD_A,PD_B,PD_C)) | AM3: =IF($A3="","",IF($AH3=1,1,$AL3)) | AN3: =IF($A3="","",IF(OR($U3="LC_SIGHT",$U3="LC_USANCE"),LGD_LC,LGD)) | AO3: =IF($A3="","",IF($W3="Y",Cov,0)) | AP3: =IF($A3="","",CHOOSE(MATCH($AK3,{"S","A","B","C"},0),Spread_S,Spread_A,Spread_B,Spread_C)) | AQ3: =IF($A3="","",CHOOSE(MATCH($AK3,{"S","A","B","C"},0),Prem_S,Prem_A,Prem_B,Prem_C)) | AR3: =IF(OR($A3="",$V3<=0),"",TSOFR3M+$AP3+$AL3*$AN3) | AS3: =IF(OR($A3="",$V3<=0),"",TSOFR3M+$AP3+$AQ3*365/$V3+$AL3*$AN3*(1-Cov)) | AT3: =IF(OR($A3="",$V3<=0),"",IF($W3="Y",$AS3,$AR3)) | AU3: =IF(OR($A3="",$V3<=0),"",IF($AS3<$AR3,"부보 유리","무보험 유리")) | AV3: =IF($A3="","",$Y3*($V3+Grace)/30) | AW3: =IF($A3="","",CHOOSE(MATCH($AK3,{"S","A","B","C"},0),$AV3,Cap_A,Cap_B,Cap_C_OA)) | AX3: =IF($A3="","",IF($W3="Y",$X3,0)) | AY3: =IF($A3="","",Equity_USD*CHOOSE(MATCH($AK3,{"S","A","B","C"},0),s_S,s_A,s_B,s_C)) | AZ3: =IF($A3="","",'13_EarlyWarning'!$AH6) | BA3: =IF($A3="","",IF(OR($U3="LC_SIGHT",$U3="LC_USANCE",$U3="TT_ADV"),"대상 아님","대상")) | BB3: =IF($A3="","",IF(OR($BA3="대상 아님",$AZ3<>"",$AH3=1),0,MIN($AV3,$AW3,$AX3+$AY3))) | BC3: =IF($A3="","",IF($AG3=1,MIN(StratMin*$AB3,$BB3),0)) | BD3: =IF($A3="","",IF(OR($V3<=0,$BB3<=0),0,Util*(GM*365/$V3-$AT3))) | BE3: =IF($A3="","",Util*$AL3*$AN3*(1-$AO3)) | BF3: =IF($A3="","",IF($AC3="","0-2",IF($AC3<=2,"0-2",IF($AC3=3,"3",IF($AC3<=5,"4-5","6-7"))))) | BG3: =IF($A3="","",$Z3*$AM3*$AN3*(1-$AO3)) | BH3: =IF($A3="","",$Z3*(TSOFR3M+$AP3)*$V3/DayBasis) | BI3: =IF($A3="","",$C3+$Z3*1E-13)
AK4: =IF($A4="","",IF(GradeRule="quantile",$I4,$F4)) | AL4: =IF($A4="","",CHOOSE(MATCH($AK4,{"S","A","B","C"},0),PD_S,PD_A,PD_B,PD_C)) | AM4: =IF($A4="","",IF($AH4=1,1,$AL4)) | AN4: =IF($A4="","",IF(OR($U4="LC_SIGHT",$U4="LC_USANCE"),LGD_LC,LGD)) | AO4: =IF($A4="","",IF($W4="Y",Cov,0)) | AP4: =IF($A4="","",CHOOSE(MATCH($AK4,{"S","A","B","C"},0),Spread_S,Spread_A,Spread_B,Spread_C)) | AQ4: =IF($A4="","",CHOOSE(MATCH($AK4,{"S","A","B","C"},0),Prem_S,Prem_A,Prem_B,Prem_C)) | AR4: =IF(OR($A4="",$V4<=0),"",TSOFR3M+$AP4+$AL4*$AN4) | AS4: =IF(OR($A4="",$V4<=0),"",TSOFR3M+$AP4+$AQ4*365/$V4+$AL4*$AN4*(1-Cov)) | AT4: =IF(OR($A4="",$V4<=0),"",IF($W4="Y",$AS4,$AR4)) | AU4: =IF(OR($A4="",$V4<=0),"",IF($AS4<$AR4,"부보 유리","무보험 유리")) | AV4: =IF($A4="","",$Y4*($V4+Grace)/30) | AW4: =IF($A4="","",CHOOSE(MATCH($AK4,{"S","A","B","C"},0),$AV4,Cap_A,Cap_B,Cap_C_OA)) | AX4: =IF($A4="","",IF($W4="Y",$X4,0)) | AY4: =IF($A4="","",Equity_USD*CHOOSE(MATCH($AK4,{"S","A","B","C"},0),s_S,s_A,s_B,s_C)) | AZ4: =IF($A4="","",'13_EarlyWarning'!$AH7) | BA4: =IF($A4="","",IF(OR($U4="LC_SIGHT",$U4="LC_USANCE",$U4="TT_ADV"),"대상 아님","대상")) | BB4: =IF($A4="","",IF(OR($BA4="대상 아님",$AZ4<>"",$AH4=1),0,MIN($AV4,$AW4,$AX4+$AY4))) | BC4: =IF($A4="","",IF($AG4=1,MIN(StratMin*$AB4,$BB4),0)) | BD4: =IF($A4="","",IF(OR($V4<=0,$BB4<=0),0,Util*(GM*365/$V4-$AT4))) | BE4: =IF($A4="","",Util*$AL4*$AN4*(1-$AO4)) | BF4: =IF($A4="","",IF($AC4="","0-2",IF($AC4<=2,"0-2",IF($AC4=3,"3",IF($AC4<=5,"4-5","6-7"))))) | BG4: =IF($A4="","",$Z4*$AM4*$AN4*(1-$AO4)) | BH4: =IF($A4="","",$Z4*(TSOFR3M+$AP4)*$V4/DayBasis) | BI4: =IF($A4="","",$C4+$Z4*1E-13)
AK5: =IF($A5="","",IF(GradeRule="quantile",$I5,$F5)) | AL5: =IF($A5="","",CHOOSE(MATCH($AK5,{"S","A","B","C"},0),PD_S,PD_A,PD_B,PD_C)) | AM5: =IF($A5="","",IF($AH5=1,1,$AL5)) | AN5: =IF($A5="","",IF(OR($U5="LC_SIGHT",$U5="LC_USANCE"),LGD_LC,LGD)) | AO5: =IF($A5="","",IF($W5="Y",Cov,0)) | AP5: =IF($A5="","",CHOOSE(MATCH($AK5,{"S","A","B","C"},0),Spread_S,Spread_A,Spread_B,Spread_C)) | AQ5: =IF($A5="","",CHOOSE(MATCH($AK5,{"S","A","B","C"},0),Prem_S,Prem_A,Prem_B,Prem_C)) | AR5: =IF(OR($A5="",$V5<=0),"",TSOFR3M+$AP5+$AL5*$AN5) | AS5: =IF(OR($A5="",$V5<=0),"",TSOFR3M+$AP5+$AQ5*365/$V5+$AL5*$AN5*(1-Cov)) | AT5: =IF(OR($A5="",$V5<=0),"",IF($W5="Y",$AS5,$AR5)) | AU5: =IF(OR($A5="",$V5<=0),"",IF($AS5<$AR5,"부보 유리","무보험 유리")) | AV5: =IF($A5="","",$Y5*($V5+Grace)/30) | AW5: =IF($A5="","",CHOOSE(MATCH($AK5,{"S","A","B","C"},0),$AV5,Cap_A,Cap_B,Cap_C_OA)) | AX5: =IF($A5="","",IF($W5="Y",$X5,0)) | AY5: =IF($A5="","",Equity_USD*CHOOSE(MATCH($AK5,{"S","A","B","C"},0),s_S,s_A,s_B,s_C)) | AZ5: =IF($A5="","",'13_EarlyWarning'!$AH8) | BA5: =IF($A5="","",IF(OR($U5="LC_SIGHT",$U5="LC_USANCE",$U5="TT_ADV"),"대상 아님","대상")) | BB5: =IF($A5="","",IF(OR($BA5="대상 아님",$AZ5<>"",$AH5=1),0,MIN($AV5,$AW5,$AX5+$AY5))) | BC5: =IF($A5="","",IF($AG5=1,MIN(StratMin*$AB5,$BB5),0)) | BD5: =IF($A5="","",IF(OR($V5<=0,$BB5<=0),0,Util*(GM*365/$V5-$AT5))) | BE5: =IF($A5="","",Util*$AL5*$AN5*(1-$AO5)) | BF5: =IF($A5="","",IF($AC5="","0-2",IF($AC5<=2,"0-2",IF($AC5=3,"3",IF($AC5<=5,"4-5","6-7"))))) | BG5: =IF($A5="","",$Z5*$AM5*$AN5*(1-$AO5)) | BH5: =IF($A5="","",$Z5*(TSOFR3M+$AP5)*$V5/DayBasis) | BI5: =IF($A5="","",$C5+$Z5*1E-13)
AK6: =IF($A6="","",IF(GradeRule="quantile",$I6,$F6)) | AL6: =IF($A6="","",CHOOSE(MATCH($AK6,{"S","A","B","C"},0),PD_S,PD_A,PD_B,PD_C)) | AM6: =IF($A6="","",IF($AH6=1,1,$AL6)) | AN6: =IF($A6="","",IF(OR($U6="LC_SIGHT",$U6="LC_USANCE"),LGD_LC,LGD)) | AO6: =IF($A6="","",IF($W6="Y",Cov,0)) | AP6: =IF($A6="","",CHOOSE(MATCH($AK6,{"S","A","B","C"},0),Spread_S,Spread_A,Spread_B,Spread_C)) | AQ6: =IF($A6="","",CHOOSE(MATCH($AK6,{"S","A","B","C"},0),Prem_S,Prem_A,Prem_B,Prem_C)) | AR6: =IF(OR($A6="",$V6<=0),"",TSOFR3M+$AP6+$AL6*$AN6) | AS6: =IF(OR($A6="",$V6<=0),"",TSOFR3M+$AP6+$AQ6*365/$V6+$AL6*$AN6*(1-Cov)) | AT6: =IF(OR($A6="",$V6<=0),"",IF($W6="Y",$AS6,$AR6)) | AU6: =IF(OR($A6="",$V6<=0),"",IF($AS6<$AR6,"부보 유리","무보험 유리")) | AV6: =IF($A6="","",$Y6*($V6+Grace)/30) | AW6: =IF($A6="","",CHOOSE(MATCH($AK6,{"S","A","B","C"},0),$AV6,Cap_A,Cap_B,Cap_C_OA)) | AX6: =IF($A6="","",IF($W6="Y",$X6,0)) | AY6: =IF($A6="","",Equity_USD*CHOOSE(MATCH($AK6,{"S","A","B","C"},0),s_S,s_A,s_B,s_C)) | AZ6: =IF($A6="","",'13_EarlyWarning'!$AH9) | BA6: =IF($A6="","",IF(OR($U6="LC_SIGHT",$U6="LC_USANCE",$U6="TT_ADV"),"대상 아님","대상")) | BB6: =IF($A6="","",IF(OR($BA6="대상 아님",$AZ6<>"",$AH6=1),0,MIN($AV6,$AW6,$AX6+$AY6))) | BC6: =IF($A6="","",IF($AG6=1,MIN(StratMin*$AB6,$BB6),0)) | BD6: =IF($A6="","",IF(OR($V6<=0,$BB6<=0),0,Util*(GM*365/$V6-$AT6))) | BE6: =IF($A6="","",Util*$AL6*$AN6*(1-$AO6)) | BF6: =IF($A6="","",IF($AC6="","0-2",IF($AC6<=2,"0-2",IF($AC6=3,"3",IF($AC6<=5,"4-5","6-7"))))) | BG6: =IF($A6="","",$Z6*$AM6*$AN6*(1-$AO6)) | BH6: =IF($A6="","",$Z6*(TSOFR3M+$AP6)*$V6/DayBasis) | BI6: =IF($A6="","",$C6+$Z6*1E-13)
AK7: =IF($A7="","",IF(GradeRule="quantile",$I7,$F7)) | AL7: =IF($A7="","",CHOOSE(MATCH($AK7,{"S","A","B","C"},0),PD_S,PD_A,PD_B,PD_C)) | AM7: =IF($A7="","",IF($AH7=1,1,$AL7)) | AN7: =IF($A7="","",IF(OR($U7="LC_SIGHT",$U7="LC_USANCE"),LGD_LC,LGD)) | AO7: =IF($A7="","",IF($W7="Y",Cov,0)) | AP7: =IF($A7="","",CHOOSE(MATCH($AK7,{"S","A","B","C"},0),Spread_S,Spread_A,Spread_B,Spread_C)) | AQ7: =IF($A7="","",CHOOSE(MATCH($AK7,{"S","A","B","C"},0),Prem_S,Prem_A,Prem_B,Prem_C)) | AR7: =IF(OR($A7="",$V7<=0),"",TSOFR3M+$AP7+$AL7*$AN7) | AS7: =IF(OR($A7="",$V7<=0),"",TSOFR3M+$AP7+$AQ7*365/$V7+$AL7*$AN7*(1-Cov)) | AT7: =IF(OR($A7="",$V7<=0),"",IF($W7="Y",$AS7,$AR7)) | AU7: =IF(OR($A7="",$V7<=0),"",IF($AS7<$AR7,"부보 유리","무보험 유리")) | AV7: =IF($A7="","",$Y7*($V7+Grace)/30) | AW7: =IF($A7="","",CHOOSE(MATCH($AK7,{"S","A","B","C"},0),$AV7,Cap_A,Cap_B,Cap_C_OA)) | AX7: =IF($A7="","",IF($W7="Y",$X7,0)) | AY7: =IF($A7="","",Equity_USD*CHOOSE(MATCH($AK7,{"S","A","B","C"},0),s_S,s_A,s_B,s_C)) | AZ7: =IF($A7="","",'13_EarlyWarning'!$AH10) | BA7: =IF($A7="","",IF(OR($U7="LC_SIGHT",$U7="LC_USANCE",$U7="TT_ADV"),"대상 아님","대상")) | BB7: =IF($A7="","",IF(OR($BA7="대상 아님",$AZ7<>"",$AH7=1),0,MIN($AV7,$AW7,$AX7+$AY7))) | BC7: =IF($A7="","",IF($AG7=1,MIN(StratMin*$AB7,$BB7),0)) | BD7: =IF($A7="","",IF(OR($V7<=0,$BB7<=0),0,Util*(GM*365/$V7-$AT7))) | BE7: =IF($A7="","",Util*$AL7*$AN7*(1-$AO7)) | BF7: =IF($A7="","",IF($AC7="","0-2",IF($AC7<=2,"0-2",IF($AC7=3,"3",IF($AC7<=5,"4-5","6-7"))))) | BG7: =IF($A7="","",$Z7*$AM7*$AN7*(1-$AO7)) | BH7: =IF($A7="","",$Z7*(TSOFR3M+$AP7)*$V7/DayBasis) | BI7: =IF($A7="","",$C7+$Z7*1E-13)
AK8: =IF($A8="","",IF(GradeRule="quantile",$I8,$F8)) | AL8: =IF($A8="","",CHOOSE(MATCH($AK8,{"S","A","B","C"},0),PD_S,PD_A,PD_B,PD_C)) | AM8: =IF($A8="","",IF($AH8=1,1,$AL8)) | AN8: =IF($A8="","",IF(OR($U8="LC_SIGHT",$U8="LC_USANCE"),LGD_LC,LGD)) | AO8: =IF($A8="","",IF($W8="Y",Cov,0)) | AP8: =IF($A8="","",CHOOSE(MATCH($AK8,{"S","A","B","C"},0),Spread_S,Spread_A,Spread_B,Spread_C)) | AQ8: =IF($A8="","",CHOOSE(MATCH($AK8,{"S","A","B","C"},0),Prem_S,Prem_A,Prem_B,Prem_C)) | AR8: =IF(OR($A8="",$V8<=0),"",TSOFR3M+$AP8+$AL8*$AN8) | AS8: =IF(OR($A8="",$V8<=0),"",TSOFR3M+$AP8+$AQ8*365/$V8+$AL8*$AN8*(1-Cov)) | AT8: =IF(OR($A8="",$V8<=0),"",IF($W8="Y",$AS8,$AR8)) | AU8: =IF(OR($A8="",$V8<=0),"",IF($AS8<$AR8,"부보 유리","무보험 유리")) | AV8: =IF($A8="","",$Y8*($V8+Grace)/30) | AW8: =IF($A8="","",CHOOSE(MATCH($AK8,{"S","A","B","C"},0),$AV8,Cap_A,Cap_B,Cap_C_OA)) | AX8: =IF($A8="","",IF($W8="Y",$X8,0)) | AY8: =IF($A8="","",Equity_USD*CHOOSE(MATCH($AK8,{"S","A","B","C"},0),s_S,s_A,s_B,s_C)) | AZ8: =IF($A8="","",'13_EarlyWarning'!$AH11) | BA8: =IF($A8="","",IF(OR($U8="LC_SIGHT",$U8="LC_USANCE",$U8="TT_ADV"),"대상 아님","대상")) | BB8: =IF($A8="","",IF(OR($BA8="대상 아님",$AZ8<>"",$AH8=1),0,MIN($AV8,$AW8,$AX8+$AY8))) | BC8: =IF($A8="","",IF($AG8=1,MIN(StratMin*$AB8,$BB8),0)) | BD8: =IF($A8="","",IF(OR($V8<=0,$BB8<=0),0,Util*(GM*365/$V8-$AT8))) | BE8: =IF($A8="","",Util*$AL8*$AN8*(1-$AO8)) | BF8: =IF($A8="","",IF($AC8="","0-2",IF($AC8<=2,"0-2",IF($AC8=3,"3",IF($AC8<=5,"4-5","6-7"))))) | BG8: =IF($A8="","",$Z8*$AM8*$AN8*(1-$AO8)) | BH8: =IF($A8="","",$Z8*(TSOFR3M+$AP8)*$V8/DayBasis) | BI8: =IF($A8="","",$C8+$Z8*1E-13)
AK9: =IF($A9="","",IF(GradeRule="quantile",$I9,$F9)) | AL9: =IF($A9="","",CHOOSE(MATCH($AK9,{"S","A","B","C"},0),PD_S,PD_A,PD_B,PD_C)) | AM9: =IF($A9="","",IF($AH9=1,1,$AL9)) | AN9: =IF($A9="","",IF(OR($U9="LC_SIGHT",$U9="LC_USANCE"),LGD_LC,LGD)) | AO9: =IF($A9="","",IF($W9="Y",Cov,0)) | AP9: =IF($A9="","",CHOOSE(MATCH($AK9,{"S","A","B","C"},0),Spread_S,Spread_A,Spread_B,Spread_C)) | AQ9: =IF($A9="","",CHOOSE(MATCH($AK9,{"S","A","B","C"},0),Prem_S,Prem_A,Prem_B,Prem_C)) | AR9: =IF(OR($A9="",$V9<=0),"",TSOFR3M+$AP9+$AL9*$AN9) | AS9: =IF(OR($A9="",$V9<=0),"",TSOFR3M+$AP9+$AQ9*365/$V9+$AL9*$AN9*(1-Cov)) | AT9: =IF(OR($A9="",$V9<=0),"",IF($W9="Y",$AS9,$AR9)) | AU9: =IF(OR($A9="",$V9<=0),"",IF($AS9<$AR9,"부보 유리","무보험 유리")) | AV9: =IF($A9="","",$Y9*($V9+Grace)/30) | AW9: =IF($A9="","",CHOOSE(MATCH($AK9,{"S","A","B","C"},0),$AV9,Cap_A,Cap_B,Cap_C_OA)) | AX9: =IF($A9="","",IF($W9="Y",$X9,0)) | AY9: =IF($A9="","",Equity_USD*CHOOSE(MATCH($AK9,{"S","A","B","C"},0),s_S,s_A,s_B,s_C)) | AZ9: =IF($A9="","",'13_EarlyWarning'!$AH12) | BA9: =IF($A9="","",IF(OR($U9="LC_SIGHT",$U9="LC_USANCE",$U9="TT_ADV"),"대상 아님","대상")) | BB9: =IF($A9="","",IF(OR($BA9="대상 아님",$AZ9<>"",$AH9=1),0,MIN($AV9,$AW9,$AX9+$AY9))) | BC9: =IF($A9="","",IF($AG9=1,MIN(StratMin*$AB9,$BB9),0)) | BD9: =IF($A9="","",IF(OR($V9<=0,$BB9<=0),0,Util*(GM*365/$V9-$AT9))) | BE9: =IF($A9="","",Util*$AL9*$AN9*(1-$AO9)) | BF9: =IF($A9="","",IF($AC9="","0-2",IF($AC9<=2,"0-2",IF($AC9=3,"3",IF($AC9<=5,"4-5","6-7"))))) | BG9: =IF($A9="","",$Z9*$AM9*$AN9*(1-$AO9)) | BH9: =IF($A9="","",$Z9*(TSOFR3M+$AP9)*$V9/DayBasis) | BI9: =IF($A9="","",$C9+$Z9*1E-13)
AK10: =IF($A10="","",IF(GradeRule="quantile",$I10,$F10)) | AL10: =IF($A10="","",CHOOSE(MATCH($AK10,{"S","A","B","C"},0),PD_S,PD_A,PD_B,PD_C)) | AM10: =IF($A10="","",IF($AH10=1,1,$AL10)) | AN10: =IF($A10="","",IF(OR($U10="LC_SIGHT",$U10="LC_USANCE"),LGD_LC,LGD)) | AO10: =IF($A10="","",IF($W10="Y",Cov,0)) | AP10: =IF($A10="","",CHOOSE(MATCH($AK10,{"S","A","B","C"},0),Spread_S,Spread_A,Spread_B,Spread_C)) | AQ10: =IF($A10="","",CHOOSE(MATCH($AK10,{"S","A","B","C"},0),Prem_S,Prem_A,Prem_B,Prem_C)) | AR10: =IF(OR($A10="",$V10<=0),"",TSOFR3M+$AP10+$AL10*$AN10) | AS10: =IF(OR($A10="",$V10<=0),"",TSOFR3M+$AP10+$AQ10*365/$V10+$AL10*$AN10*(1-Cov)) | AT10: =IF(OR($A10="",$V10<=0),"",IF($W10="Y",$AS10,$AR10)) | AU10: =IF(OR($A10="",$V10<=0),"",IF($AS10<$AR10,"부보 유리","무보험 유리")) | AV10: =IF($A10="","",$Y10*($V10+Grace)/30) | AW10: =IF($A10="","",CHOOSE(MATCH($AK10,{"S","A","B","C"},0),$AV10,Cap_A,Cap_B,Cap_C_OA)) | AX10: =IF($A10="","",IF($W10="Y",$X10,0)) | AY10: =IF($A10="","",Equity_USD*CHOOSE(MATCH($AK10,{"S","A","B","C"},0),s_S,s_A,s_B,s_C)) | AZ10: =IF($A10="","",'13_EarlyWarning'!$AH13) | BA10: =IF($A10="","",IF(OR($U10="LC_SIGHT",$U10="LC_USANCE",$U10="TT_ADV"),"대상 아님","대상")) | BB10: =IF($A10="","",IF(OR($BA10="대상 아님",$AZ10<>"",$AH10=1),0,MIN($AV10,$AW10,$AX10+$AY10))) | BC10: =IF($A10="","",IF($AG10=1,MIN(StratMin*$AB10,$BB10),0)) | BD10: =IF($A10="","",IF(OR($V10<=0,$BB10<=0),0,Util*(GM*365/$V10-$AT10))) | BE10: =IF($A10="","",Util*$AL10*$AN10*(1-$AO10)) | BF10: =IF($A10="","",IF($AC10="","0-2",IF($AC10<=2,"0-2",IF($AC10=3,"3",IF($AC10<=5,"4-5","6-7"))))) | BG10: =IF($A10="","",$Z10*$AM10*$AN10*(1-$AO10)) | BH10: =IF($A10="","",$Z10*(TSOFR3M+$AP10)*$V10/DayBasis) | BI10: =IF($A10="","",$C10+$Z10*1E-13)
AK11: =IF($A11="","",IF(GradeRule="quantile",$I11,$F11)) | AL11: =IF($A11="","",CHOOSE(MATCH($AK11,{"S","A","B","C"},0),PD_S,PD_A,PD_B,PD_C)) | AM11: =IF($A11="","",IF($AH11=1,1,$AL11)) | AN11: =IF($A11="","",IF(OR($U11="LC_SIGHT",$U11="LC_USANCE"),LGD_LC,LGD)) | AO11: =IF($A11="","",IF($W11="Y",Cov,0)) | AP11: =IF($A11="","",CHOOSE(MATCH($AK11,{"S","A","B","C"},0),Spread_S,Spread_A,Spread_B,Spread_C)) | AQ11: =IF($A11="","",CHOOSE(MATCH($AK11,{"S","A","B","C"},0),Prem_S,Prem_A,Prem_B,Prem_C)) | AR11: =IF(OR($A11="",$V11<=0),"",TSOFR3M+$AP11+$AL11*$AN11) | AS11: =IF(OR($A11="",$V11<=0),"",TSOFR3M+$AP11+$AQ11*365/$V11+$AL11*$AN11*(1-Cov)) | AT11: =IF(OR($A11="",$V11<=0),"",IF($W11="Y",$AS11,$AR11)) | AU11: =IF(OR($A11="",$V11<=0),"",IF($AS11<$AR11,"부보 유리","무보험 유리")) | AV11: =IF($A11="","",$Y11*($V11+Grace)/30) | AW11: =IF($A11="","",CHOOSE(MATCH($AK11,{"S","A","B","C"},0),$AV11,Cap_A,Cap_B,Cap_C_OA)) | AX11: =IF($A11="","",IF($W11="Y",$X11,0)) | AY11: =IF($A11="","",Equity_USD*CHOOSE(MATCH($AK11,{"S","A","B","C"},0),s_S,s_A,s_B,s_C)) | AZ11: =IF($A11="","",'13_EarlyWarning'!$AH14) | BA11: =IF($A11="","",IF(OR($U11="LC_SIGHT",$U11="LC_USANCE",$U11="TT_ADV"),"대상 아님","대상")) | BB11: =IF($A11="","",IF(OR($BA11="대상 아님",$AZ11<>"",$AH11=1),0,MIN($AV11,$AW11,$AX11+$AY11))) | BC11: =IF($A11="","",IF($AG11=1,MIN(StratMin*$AB11,$BB11),0)) | BD11: =IF($A11="","",IF(OR($V11<=0,$BB11<=0),0,Util*(GM*365/$V11-$AT11))) | BE11: =IF($A11="","",Util*$AL11*$AN11*(1-$AO11)) | BF11: =IF($A11="","",IF($AC11="","0-2",IF($AC11<=2,"0-2",IF($AC11=3,"3",IF($AC11<=5,"4-5","6-7"))))) | BG11: =IF($A11="","",$Z11*$AM11*$AN11*(1-$AO11)) | BH11: =IF($A11="","",$Z11*(TSOFR3M+$AP11)*$V11/DayBasis) | BI11: =IF($A11="","",$C11+$Z11*1E-13)
AK12: =IF($A12="","",IF(GradeRule="quantile",$I12,$F12)) | AL12: =IF($A12="","",CHOOSE(MATCH($AK12,{"S","A","B","C"},0),PD_S,PD_A,PD_B,PD_C)) | AM12: =IF($A12="","",IF($AH12=1,1,$AL12)) | AN12: =IF($A12="","",IF(OR($U12="LC_SIGHT",$U12="LC_USANCE"),LGD_LC,LGD)) | AO12: =IF($A12="","",IF($W12="Y",Cov,0)) | AP12: =IF($A12="","",CHOOSE(MATCH($AK12,{"S","A","B","C"},0),Spread_S,Spread_A,Spread_B,Spread_C)) | AQ12: =IF($A12="","",CHOOSE(MATCH($AK12,{"S","A","B","C"},0),Prem_S,Prem_A,Prem_B,Prem_C)) | AR12: =IF(OR($A12="",$V12<=0),"",TSOFR3M+$AP12+$AL12*$AN12) | AS12: =IF(OR($A12="",$V12<=0),"",TSOFR3M+$AP12+$AQ12*365/$V12+$AL12*$AN12*(1-Cov)) | AT12: =IF(OR($A12="",$V12<=0),"",IF($W12="Y",$AS12,$AR12)) | AU12: =IF(OR($A12="",$V12<=0),"",IF($AS12<$AR12,"부보 유리","무보험 유리")) | AV12: =IF($A12="","",$Y12*($V12+Grace)/30) | AW12: =IF($A12="","",CHOOSE(MATCH($AK12,{"S","A","B","C"},0),$AV12,Cap_A,Cap_B,Cap_C_OA)) | AX12: =IF($A12="","",IF($W12="Y",$X12,0)) | AY12: =IF($A12="","",Equity_USD*CHOOSE(MATCH($AK12,{"S","A","B","C"},0),s_S,s_A,s_B,s_C)) | AZ12: =IF($A12="","",'13_EarlyWarning'!$AH15) | BA12: =IF($A12="","",IF(OR($U12="LC_SIGHT",$U12="LC_USANCE",$U12="TT_ADV"),"대상 아님","대상")) | BB12: =IF($A12="","",IF(OR($BA12="대상 아님",$AZ12<>"",$AH12=1),0,MIN($AV12,$AW12,$AX12+$AY12))) | BC12: =IF($A12="","",IF($AG12=1,MIN(StratMin*$AB12,$BB12),0)) | BD12: =IF($A12="","",IF(OR($V12<=0,$BB12<=0),0,Util*(GM*365/$V12-$AT12))) | BE12: =IF($A12="","",Util*$AL12*$AN12*(1-$AO12)) | BF12: =IF($A12="","",IF($AC12="","0-2",IF($AC12<=2,"0-2",IF($AC12=3,"3",IF($AC12<=5,"4-5","6-7"))))) | BG12: =IF($A12="","",$Z12*$AM12*$AN12*(1-$AO12)) | BH12: =IF($A12="","",$Z12*(TSOFR3M+$AP12)*$V12/DayBasis) | BI12: =IF($A12="","",$C12+$Z12*1E-13)
AK13: =IF($A13="","",IF(GradeRule="quantile",$I13,$F13)) | AL13: =IF($A13="","",CHOOSE(MATCH($AK13,{"S","A","B","C"},0),PD_S,PD_A,PD_B,PD_C)) | AM13: =IF($A13="","",IF($AH13=1,1,$AL13)) | AN13: =IF($A13="","",IF(OR($U13="LC_SIGHT",$U13="LC_USANCE"),LGD_LC,LGD)) | AO13: =IF($A13="","",IF($W13="Y",Cov,0)) | AP13: =IF($A13="","",CHOOSE(MATCH($AK13,{"S","A","B","C"},0),Spread_S,Spread_A,Spread_B,Spread_C)) | AQ13: =IF($A13="","",CHOOSE(MATCH($AK13,{"S","A","B","C"},0),Prem_S,Prem_A,Prem_B,Prem_C)) | AR13: =IF(OR($A13="",$V13<=0),"",TSOFR3M+$AP13+$AL13*$AN13) | AS13: =IF(OR($A13="",$V13<=0),"",TSOFR3M+$AP13+$AQ13*365/$V13+$AL13*$AN13*(1-Cov)) | AT13: =IF(OR($A13="",$V13<=0),"",IF($W13="Y",$AS13,$AR13)) | AU13: =IF(OR($A13="",$V13<=0),"",IF($AS13<$AR13,"부보 유리","무보험 유리")) | AV13: =IF($A13="","",$Y13*($V13+Grace)/30) | AW13: =IF($A13="","",CHOOSE(MATCH($AK13,{"S","A","B","C"},0),$AV13,Cap_A,Cap_B,Cap_C_OA)) | AX13: =IF($A13="","",IF($W13="Y",$X13,0)) | AY13: =IF($A13="","",Equity_USD*CHOOSE(MATCH($AK13,{"S","A","B","C"},0),s_S,s_A,s_B,s_C)) | AZ13: =IF($A13="","",'13_EarlyWarning'!$AH16) | BA13: =IF($A13="","",IF(OR($U13="LC_SIGHT",$U13="LC_USANCE",$U13="TT_ADV"),"대상 아님","대상")) | BB13: =IF($A13="","",IF(OR($BA13="대상 아님",$AZ13<>"",$AH13=1),0,MIN($AV13,$AW13,$AX13+$AY13))) | BC13: =IF($A13="","",IF($AG13=1,MIN(StratMin*$AB13,$BB13),0)) | BD13: =IF($A13="","",IF(OR($V13<=0,$BB13<=0),0,Util*(GM*365/$V13-$AT13))) | BE13: =IF($A13="","",Util*$AL13*$AN13*(1-$AO13)) | BF13: =IF($A13="","",IF($AC13="","0-2",IF($AC13<=2,"0-2",IF($AC13=3,"3",IF($AC13<=5,"4-5","6-7"))))) | BG13: =IF($A13="","",$Z13*$AM13*$AN13*(1-$AO13)) | BH13: =IF($A13="","",$Z13*(TSOFR3M+$AP13)*$V13/DayBasis) | BI13: =IF($A13="","",$C13+$Z13*1E-13)
... AK151: =IF($A151="","",IF(GradeRule="quantile",$I151,$F151)) | AL151: =IF($A151="","",CHOOSE(MATCH($AK151,{"S","A","B","C"},0),PD_S,PD_A,PD_B,PD_C)) | AM151: =IF($A151="","",IF($AH151=1,1,$AL151)) | AN151: =IF($A151="","",IF(OR($U151="LC_SIGHT",$U151="LC_USANCE"),LGD_LC,LGD)) | AO151: =IF($A151="","",IF($W151="Y",Cov,0)) | AP151: =IF($A151="","",CHOOSE(MATCH($AK151,{"S","A","B","C"},0),Spread_S,Spread_A,Spread_B,Spread_C)) | AQ151: =IF($A151="","",CHOOSE(MATCH($AK151,{"S","A","B","C"},0),Prem_S,Prem_A,Prem_B,Prem_C)) | AR151: =IF(OR($A151="",$V151<=0),"",TSOFR3M+$AP151+$AL151*$AN151) | AS151: =IF(OR($A151="",$V151<=0),"",TSOFR3M+$AP151+$AQ151*365/$V151+$AL151*$AN151*(1-Cov)) | AT151: =IF(OR($A151="",$V151<=0),"",IF($W151="Y",$AS151,$AR151)) | AU151: =IF(OR($A151="",$V151<=0),"",IF($AS151<$AR151,"부보 유리","무보험 유리")) | AV151: =IF($A151="","",$Y151*($V151+Grace)/30) | AW151: =IF($A151="","",CHOOSE(MATCH($AK151,{"S","A","B","C"},0),$AV151,Cap_A,Cap_B,Cap_C_OA)) | AX151: =IF($A151="","",IF($W151="Y",$X151,0)) | AY151: =IF($A151="","",Equity_USD*CHOOSE(MATCH($AK151,{"S","A","B","C"},0),s_S,s_A,s_B,s_C)) | AZ151: =IF($A151="","",'13_EarlyWarning'!$AH154) | BA151: =IF($A151="","",IF(OR($U151="LC_SIGHT",$U151="LC_USANCE",$U151="TT_ADV"),"대상 아님","대상")) | BB151: =IF($A151="","",IF(OR($BA151="대상 아님",$AZ151<>"",$AH151=1),0,MIN($AV151,$AW151,$AX151+$AY151))) | BC151: =IF($A151="","",IF($AG151=1,MIN(StratMin*$AB151,$BB151),0)) | BD151: =IF($A151="","",IF(OR($V151<=0,$BB151<=0),0,Util*(GM*365/$V151-$AT151))) | BE151: =IF($A151="","",Util*$AL151*$AN151*(1-$AO151)) | BF151: =IF($A151="","",IF($AC151="","0-2",IF($AC151<=2,"0-2",IF($AC151=3,"3",IF($AC151<=5,"4-5","6-7"))))) | BG151: =IF($A151="","",$Z151*$AM151*$AN151*(1-$AO151)) | BH151: =IF($A151="","",$Z151*(TSOFR3M+$AP151)*$V151/DayBasis) | BI151: =IF($A151="","",$C151+$Z151*1E-13)

Sheet 03_RateBuild
A1: 03_RateBuild — 등급별 위험조정 할인율·NPV 검산(G03 §2.8)
A2: r 무보험 = TSOFR3M + Spread_g + PD_g × LGD · r 부보 = TSOFR3M + Spread_g + Prem_g × 365 ÷ Tenor + PD_g × LGD × (1 − Cov) · NPV = 금액 ÷ (1 + r × Tenor ÷ 360)
A3: 손익분기: '보험료(연환산) < PD × LGD × 보상비율'이면 부보가 유리 → A와 B 사이(G03)
A4: 검산 금액(USD) | B4: =CheckAmt | C4: 기간(일) | D4: =Tenor
A5: 등급 | B5: 자금비용 B+s | C5: EL(연) PD×LGD | D5: r 무보험 | E5: NPV 무보험 | F5: 보험료 연환산 | G5: r 부보 | H5: NPV 부보 | I5: 판정 | J5: PD 90일 | K5: G03 r 무보험 | L5: G03 NPV 무보험 | M5: G03 r 부보 | N5: G03 NPV 부보 | O5: 일치?
A6: S | B6: =TSOFR3M+Spread_S | C6: =PD_S*LGD | D6: =B6+C6 | E6: =$B$4/(1+D6*$D$4/DayBasis) | F6: =Prem_S*365/$D$4 | G6: =B6+F6+C6*(1-Cov) | H6: =$B$4/(1+G6*$D$4/DayBasis) | I6: =IF(G6<D6,"부보 유리","무보험 유리") | J6: =1-(1-PD_S)^($D$4/365) | K6: 0.0535 | L6: 98681 | M6: 0.0628 | N6: 98455 | O6: =IF(AND(ABS(D6-K6)<=0.0001,ABS(E6-L6)<=1,ABS(G6-M6)<=0.0001,ABS(H6-N6)<=1),"✔","✘ 확인")
A7: A | B7: =TSOFR3M+Spread_A | C7: =PD_A*LGD | D7: =B7+C7 | E7: =$B$4/(1+D7*$D$4/DayBasis) | F7: =Prem_A*365/$D$4 | G7: =B7+F7+C7*(1-Cov) | H7: =$B$4/(1+G7*$D$4/DayBasis) | I7: =IF(G7<D7,"부보 유리","무보험 유리") | J7: =1-(1-PD_A)^($D$4/365) | K7: 0.0645 | L7: 98414 | M7: 0.0722 | N7: 98228 | O7: =IF(AND(ABS(D7-K7)<=0.0001,ABS(E7-L7)<=1,ABS(G7-M7)<=0.0001,ABS(H7-N7)<=1),"✔","✘ 확인")
A8: B | B8: =TSOFR3M+Spread_B | C8: =PD_B*LGD | D8: =B8+C8 | E8: =$B$4/(1+D8*$D$4/DayBasis) | F8: =Prem_B*365/$D$4 | G8: =B8+F8+C8*(1-Cov) | H8: =$B$4/(1+G8*$D$4/DayBasis) | I8: =IF(G8<D8,"부보 유리","무보험 유리") | J8: =1-(1-PD_B)^($D$4/365) | K8: 0.0845 | L8: 97932 | M8: 0.0819 | N8: 97992 | O8: =IF(AND(ABS(D8-K8)<=0.0001,ABS(E8-L8)<=1,ABS(G8-M8)<=0.0001,ABS(H8-N8)<=1),"✔","✘ 확인")
A9: C | B9: =TSOFR3M+Spread_C | C9: =PD_C*LGD | D9: =B9+C9 | E9: =$B$4/(1+D9*$D$4/DayBasis) | F9: =Prem_C*365/$D$4 | G9: =B9+F9+C9*(1-Cov) | H9: =$B$4/(1+G9*$D$4/DayBasis) | I9: =IF(G9<D9,"부보 유리","무보험 유리") | J9: =1-(1-PD_C)^($D$4/365) | K9: 0.1255 | L9: 96959 | M9: 0.109 | N9: 97347 | O9: =IF(AND(ABS(D9-K9)<=0.0001,ABS(E9-L9)<=1,ABS(G9-M9)<=0.0001,ABS(H9-N9)<=1),"✔","✘ 확인")
A11: 메모 | B11: G03 표의 A등급 r 부보 7.22%는 반올림 차이(정확히 7.214%) — NPV 98,228달러는 일치. 일치 판정 허용폭: 금리 0.01%p · NPV 1달러
A13: 차트용 구성(%)
A14: 등급 | B14: ① Term SOFR 3M | C14: ② 은행 가산 | D14: ③ 보험료(연환산) | E14: ④ EL(PD×LGD×(1−Cov))
A15: S | B15: =TSOFR3M | C15: =Spread_S | D15: =F6 | E15: =C6*(1-Cov)
A16: A | B16: =TSOFR3M | C16: =Spread_A | D16: =F7 | E16: =C7*(1-Cov)
A17: B | B17: =TSOFR3M | C17: =Spread_B | D17: =F8 | E17: =C8*(1-Cov)
A18: C | B18: =TSOFR3M | C18: =Spread_C | D18: =F9 | E18: =C9*(1-Cov)

Sheet 04_AR_Ledger
A1: 04_AR_Ledger — G03 예제 원장 R1~R7(🔵 유동성 갭 입력, 금액 USD천)
A2: 기대입금 주 = 만기 주 + ROUNDUP(평균지연 ÷ 7) · 기대입금액 = 금액 × (1 − PD 90일) · 매각 단위비용 = r 부보 × (만기 주 − 매입 주) × 7 + 지연일) ÷ 360
A4: 채권ID | B4: 등급 | C4: 금액(USD천) | D4: 만기 주 | E4: 평균지연(일) | F4: PD 연 | G4: PD 90일 | H4: 기대입금 주 | I4: 기대입금액 | J4: r 부보 | K4: 매각 시 잔존일 | L4: 단위비용 | M4: 매각 가능(1)
A5: R1 | B5: S | C5: 120 | D5: 2 | E5: 0 | F5: =CHOOSE(MATCH(B5,{"S","A","B","C"},0),PD_S,PD_A,PD_B,PD_C) | G5: =1-(1-F5)^(Tenor/365) | H5: =D5+ROUNDUP(E5/7,0) | I5: =C5*(1-G5) | J5: =INDEX('03_RateBuild'!$G$6:$G$9,MATCH(B5,'03_RateBuild'!$A$6:$A$9,0)) | K5: =(D5-SaleWeek)*7+E5 | L5: =J5*K5/DayBasis | M5: =IF(H5>SaleWeek,1,0)
A6: R2 | B6: A | C6: 100 | D6: 3 | E6: 3 | F6: =CHOOSE(MATCH(B6,{"S","A","B","C"},0),PD_S,PD_A,PD_B,PD_C) | G6: =1-(1-F6)^(Tenor/365) | H6: =D6+ROUNDUP(E6/7,0) | I6: =C6*(1-G6) | J6: =INDEX('03_RateBuild'!$G$6:$G$9,MATCH(B6,'03_RateBuild'!$A$6:$A$9,0)) | K6: =(D6-SaleWeek)*7+E6 | L6: =J6*K6/DayBasis | M6: =IF(H6>SaleWeek,1,0)
A7: R3 | B7: B | C7: 90 | D7: 4 | E7: 10 | F7: =CHOOSE(MATCH(B7,{"S","A","B","C"},0),PD_S,PD_A,PD_B,PD_C) | G7: =1-(1-F7)^(Tenor/365) | H7: =D7+ROUNDUP(E7/7,0) | I7: =C7*(1-G7) | J7: =INDEX('03_RateBuild'!$G$6:$G$9,MATCH(B7,'03_RateBuild'!$A$6:$A$9,0)) | K7: =(D7-SaleWeek)*7+E7 | L7: =J7*K7/DayBasis | M7: =IF(H7>SaleWeek,1,0)
A8: R4 | B8: C | C8: 80 | D8: 5 | E8: 25 | F8: =CHOOSE(MATCH(B8,{"S","A","B","C"},0),PD_S,PD_A,PD_B,PD_C) | G8: =1-(1-F8)^(Tenor/365) | H8: =D8+ROUNDUP(E8/7,0) | I8: =C8*(1-G8) | J8: =INDEX('03_RateBuild'!$G$6:$G$9,MATCH(B8,'03_RateBuild'!$A$6:$A$9,0)) | K8: =(D8-SaleWeek)*7+E8 | L8: =J8*K8/DayBasis | M8: =IF(H8>SaleWeek,1,0)
A9: R5 | B9: A | C9: 110 | D9: 6 | E9: 3 | F9: =CHOOSE(MATCH(B9,{"S","A","B","C"},0),PD_S,PD_A,PD_B,PD_C) | G9: =1-(1-F9)^(Tenor/365) | H9: =D9+ROUNDUP(E9/7,0) | I9: =C9*(1-G9) | J9: =INDEX('03_RateBuild'!$G$6:$G$9,MATCH(B9,'03_RateBuild'!$A$6:$A$9,0)) | K9: =(D9-SaleWeek)*7+E9 | L9: =J9*K9/DayBasis | M9: =IF(H9>SaleWeek,1,0)
A10: R6 | B10: S | C10: 130 | D10: 7 | E10: 0 | F10: =CHOOSE(MATCH(B10,{"S","A","B","C"},0),PD_S,PD_A,PD_B,PD_C) | G10: =1-(1-F10)^(Tenor/365) | H10: =D10+ROUNDUP(E10/7,0) | I10: =C10*(1-G10) | J10: =INDEX('03_RateBuild'!$G$6:$G$9,MATCH(B10,'03_RateBuild'!$A$6:$A$9,0)) | K10: =(D10-SaleWeek)*7+E10 | L10: =J10*K10/DayBasis | M10: =IF(H10>SaleWeek,1,0)
A11: R7 | B11: B | C11: 70 | D11: 8 | E11: 10 | F11: =CHOOSE(MATCH(B11,{"S","A","B","C"},0),PD_S,PD_A,PD_B,PD_C) | G11: =1-(1-F11)^(Tenor/365) | H11: =D11+ROUNDUP(E11/7,0) | I11: =C11*(1-G11) | J11: =INDEX('03_RateBuild'!$G$6:$G$9,MATCH(B11,'03_RateBuild'!$A$6:$A$9,0)) | K11: =(D11-SaleWeek)*7+E11 | L11: =J11*K11/DayBasis | M11: =IF(H11>SaleWeek,1,0)

Sheet 05_NPV
A1: 05_NPV — 은행 견적 대조(하나은행 고시) + 바이어별 채권 NPV
A2: 환가료 = 금액 × 환가료율 × 일수 ÷ 360(USD) · 실효 = (환가료 + 수수료) ÷ 금액 × 360 ÷ 일수 [G03 §2.8 Step 3]
A4: 매입 금액(USD) | B4: =CheckAmt
A5: 일수 | B5: 92
A6: 환가료율(하나 92일) | B6: =Hana92
A7: 환가료(USD) | B7: =B4*B6*B5/DayBasis | C7: 1669.54 | D7: =IF(ABS(B7-C7)<0.01,"✔ G03 일치","✘")
A8: 매입수수료(USD) = ₩20,000 ÷ 원/달러 | B8: =Fee_KRW/USDKRW
A9: 합계(USD) | B9: =B7+B8
A10: 연환산 실효비용 | B10: =B9/B4*DayBasis/B5 | C10: 0.0659 | D10: =IF(ABS(B10-C10)<0.00005,"✔ G03 일치","✘")
A11: 31일이면 환가료(USD) | B11: =B4*Hana31*31/DayBasis | C11: 495.01 | D11: =IF(ABS(B11-C11)<0.01,"✔ G03 일치","✘")
A12: 읽는 법 | B12: 실효 6.59%는 A~B등급 '자금비용 + EL' 구간(6.45~8.45%) 안 → 은행 고시 환가료 = 우대 전 상한
A14: buyer_id | B14: 등급 | C14: 미결 잔액(USD) | D14: 결제기간(일) | E14: r 무보험 | F14: r 부보 | G14: NPV 무보험 | H14: NPV 부보 | I14: 부보 판정 | J14: 현재 부보 | K14: 판정과 다름
A15: =IF('02_Buyers'!$A2="","",'02_Buyers'!$A2) | B15: =IF($A15="","",'02_Buyers'!$AK2) | C15: =IF($A15="","",'02_Buyers'!$Z2) | D15: =IF($A15="","",'02_Buyers'!$V2) | E15: =IF($A15="","",'02_Buyers'!$AR2) | F15: =IF($A15="","",'02_Buyers'!$AS2) | G15: =IF(OR($A15="",$E15=""),"",$C15/(1+$E15*$D15/DayBasis)) | H15: =IF(OR($A15="",$F15=""),"",$C15/(1+$F15*$D15/DayBasis)) | I15: =IF($A15="","",'02_Buyers'!$AU2) | J15: =IF($A15="","",'02_Buyers'!$W2) | K15: =IF(OR($A15="",$I15=""),"",IF(OR(AND($I15="부보 유리",$J15="N"),AND($I15="무보험 유리",$J15="Y")),"검토",""))
A16: =IF('02_Buyers'!$A3="","",'02_Buyers'!$A3) | B16: =IF($A16="","",'02_Buyers'!$AK3) | C16: =IF($A16="","",'02_Buyers'!$Z3) | D16: =IF($A16="","",'02_Buyers'!$V3) | E16: =IF($A16="","",'02_Buyers'!$AR3) | F16: =IF($A16="","",'02_Buyers'!$AS3) | G16: =IF(OR($A16="",$E16=""),"",$C16/(1+$E16*$D16/DayBasis)) | H16: =IF(OR($A16="",$F16=""),"",$C16/(1+$F16*$D16/DayBasis)) | I16: =IF($A16="","",'02_Buyers'!$AU3) | J16: =IF($A16="","",'02_Buyers'!$W3) | K16: =IF(OR($A16="",$I16=""),"",IF(OR(AND($I16="부보 유리",$J16="N"),AND($I16="무보험 유리",$J16="Y")),"검토",""))
A17: =IF('02_Buyers'!$A4="","",'02_Buyers'!$A4) | B17: =IF($A17="","",'02_Buyers'!$AK4) | C17: =IF($A17="","",'02_Buyers'!$Z4) | D17: =IF($A17="","",'02_Buyers'!$V4) | E17: =IF($A17="","",'02_Buyers'!$AR4) | F17: =IF($A17="","",'02_Buyers'!$AS4) | G17: =IF(OR($A17="",$E17=""),"",$C17/(1+$E17*$D17/DayBasis)) | H17: =IF(OR($A17="",$F17=""),"",$C17/(1+$F17*$D17/DayBasis)) | I17: =IF($A17="","",'02_Buyers'!$AU4) | J17: =IF($A17="","",'02_Buyers'!$W4) | K17: =IF(OR($A17="",$I17=""),"",IF(OR(AND($I17="부보 유리",$J17="N"),AND($I17="무보험 유리",$J17="Y")),"검토",""))
A18: =IF('02_Buyers'!$A5="","",'02_Buyers'!$A5) | B18: =IF($A18="","",'02_Buyers'!$AK5) | C18: =IF($A18="","",'02_Buyers'!$Z5) | D18: =IF($A18="","",'02_Buyers'!$V5) | E18: =IF($A18="","",'02_Buyers'!$AR5) | F18: =IF($A18="","",'02_Buyers'!$AS5) | G18: =IF(OR($A18="",$E18=""),"",$C18/(1+$E18*$D18/DayBasis)) | H18: =IF(OR($A18="",$F18=""),"",$C18/(1+$F18*$D18/DayBasis)) | I18: =IF($A18="","",'02_Buyers'!$AU5) | J18: =IF($A18="","",'02_Buyers'!$W5) | K18: =IF(OR($A18="",$I18=""),"",IF(OR(AND($I18="부보 유리",$J18="N"),AND($I18="무보험 유리",$J18="Y")),"검토",""))
A19: =IF('02_Buyers'!$A6="","",'02_Buyers'!$A6) | B19: =IF($A19="","",'02_Buyers'!$AK6) | C19: =IF($A19="","",'02_Buyers'!$Z6) | D19: =IF($A19="","",'02_Buyers'!$V6) | E19: =IF($A19="","",'02_Buyers'!$AR6) | F19: =IF($A19="","",'02_Buyers'!$AS6) | G19: =IF(OR($A19="",$E19=""),"",$C19/(1+$E19*$D19/DayBasis)) | H19: =IF(OR($A19="",$F19=""),"",$C19/(1+$F19*$D19/DayBasis)) | I19: =IF($A19="","",'02_Buyers'!$AU6) | J19: =IF($A19="","",'02_Buyers'!$W6) | K19: =IF(OR($A19="",$I19=""),"",IF(OR(AND($I19="부보 유리",$J19="N"),AND($I19="무보험 유리",$J19="Y")),"검토",""))
A20: =IF('02_Buyers'!$A7="","",'02_Buyers'!$A7) | B20: =IF($A20="","",'02_Buyers'!$AK7) | C20: =IF($A20="","",'02_Buyers'!$Z7) | D20: =IF($A20="","",'02_Buyers'!$V7) | E20: =IF($A20="","",'02_Buyers'!$AR7) | F20: =IF($A20="","",'02_Buyers'!$AS7) | G20: =IF(OR($A20="",$E20=""),"",$C20/(1+$E20*$D20/DayBasis)) | H20: =IF(OR($A20="",$F20=""),"",$C20/(1+$F20*$D20/DayBasis)) | I20: =IF($A20="","",'02_Buyers'!$AU7) | J20: =IF($A20="","",'02_Buyers'!$W7) | K20: =IF(OR($A20="",$I20=""),"",IF(OR(AND($I20="부보 유리",$J20="N"),AND($I20="무보험 유리",$J20="Y")),"검토",""))
A21: =IF('02_Buyers'!$A8="","",'02_Buyers'!$A8) | B21: =IF($A21="","",'02_Buyers'!$AK8) | C21: =IF($A21="","",'02_Buyers'!$Z8) | D21: =IF($A21="","",'02_Buyers'!$V8) | E21: =IF($A21="","",'02_Buyers'!$AR8) | F21: =IF($A21="","",'02_Buyers'!$AS8) | G21: =IF(OR($A21="",$E21=""),"",$C21/(1+$E21*$D21/DayBasis)) | H21: =IF(OR($A21="",$F21=""),"",$C21/(1+$F21*$D21/DayBasis)) | I21: =IF($A21="","",'02_Buyers'!$AU8) | J21: =IF($A21="","",'02_Buyers'!$W8) | K21: =IF(OR($A21="",$I21=""),"",IF(OR(AND($I21="부보 유리",$J21="N"),AND($I21="무보험 유리",$J21="Y")),"검토",""))
A22: =IF('02_Buyers'!$A9="","",'02_Buyers'!$A9) | B22: =IF($A22="","",'02_Buyers'!$AK9) | C22: =IF($A22="","",'02_Buyers'!$Z9) | D22: =IF($A22="","",'02_Buyers'!$V9) | E22: =IF($A22="","",'02_Buyers'!$AR9) | F22: =IF($A22="","",'02_Buyers'!$AS9) | G22: =IF(OR($A22="",$E22=""),"",$C22/(1+$E22*$D22/DayBasis)) | H22: =IF(OR($A22="",$F22=""),"",$C22/(1+$F22*$D22/DayBasis)) | I22: =IF($A22="","",'02_Buyers'!$AU9) | J22: =IF($A22="","",'02_Buyers'!$W9) | K22: =IF(OR($A22="",$I22=""),"",IF(OR(AND($I22="부보 유리",$J22="N"),AND($I22="무보험 유리",$J22="Y")),"검토",""))
A23: =IF('02_Buyers'!$A10="","",'02_Buyers'!$A10) | B23: =IF($A23="","",'02_Buyers'!$AK10) | C23: =IF($A23="","",'02_Buyers'!$Z10) | D23: =IF($A23="","",'02_Buyers'!$V10) | E23: =IF($A23="","",'02_Buyers'!$AR10) | F23: =IF($A23="","",'02_Buyers'!$AS10) | G23: =IF(OR($A23="",$E23=""),"",$C23/(1+$E23*$D23/DayBasis)) | H23: =IF(OR($A23="",$F23=""),"",$C23/(1+$F23*$D23/DayBasis)) | I23: =IF($A23="","",'02_Buyers'!$AU10) | J23: =IF($A23="","",'02_Buyers'!$W10) | K23: =IF(OR($A23="",$I23=""),"",IF(OR(AND($I23="부보 유리",$J23="N"),AND($I23="무보험 유리",$J23="Y")),"검토",""))
A24: =IF('02_Buyers'!$A11="","",'02_Buyers'!$A11) | B24: =IF($A24="","",'02_Buyers'!$AK11) | C24: =IF($A24="","",'02_Buyers'!$Z11) | D24: =IF($A24="","",'02_Buyers'!$V11) | E24: =IF($A24="","",'02_Buyers'!$AR11) | F24: =IF($A24="","",'02_Buyers'!$AS11) | G24: =IF(OR($A24="",$E24=""),"",$C24/(1+$E24*$D24/DayBasis)) | H24: =IF(OR($A24="",$F24=""),"",$C24/(1+$F24*$D24/DayBasis)) | I24: =IF($A24="","",'02_Buyers'!$AU11) | J24: =IF($A24="","",'02_Buyers'!$W11) | K24: =IF(OR($A24="",$I24=""),"",IF(OR(AND($I24="부보 유리",$J24="N"),AND($I24="무보험 유리",$J24="Y")),"검토",""))
A25: =IF('02_Buyers'!$A12="","",'02_Buyers'!$A12) | B25: =IF($A25="","",'02_Buyers'!$AK12) | C25: =IF($A25="","",'02_Buyers'!$Z12) | D25: =IF($A25="","",'02_Buyers'!$V12) | E25: =IF($A25="","",'02_Buyers'!$AR12) | F25: =IF($A25="","",'02_Buyers'!$AS12) | G25: =IF(OR($A25="",$E25=""),"",$C25/(1+$E25*$D25/DayBasis)) | H25: =IF(OR($A25="",$F25=""),"",$C25/(1+$F25*$D25/DayBasis)) | I25: =IF($A25="","",'02_Buyers'!$AU12) | J25: =IF($A25="","",'02_Buyers'!$W12) | K25: =IF(OR($A25="",$I25=""),"",IF(OR(AND($I25="부보 유리",$J25="N"),AND($I25="무보험 유리",$J25="Y")),"검토",""))
A26: =IF('02_Buyers'!$A13="","",'02_Buyers'!$A13) | B26: =IF($A26="","",'02_Buyers'!$AK13) | C26: =IF($A26="","",'02_Buyers'!$Z13) | D26: =IF($A26="","",'02_Buyers'!$V13) | E26: =IF($A26="","",'02_Buyers'!$AR13) | F26: =IF($A26="","",'02_Buyers'!$AS13) | G26: =IF(OR($A26="",$E26=""),"",$C26/(1+$E26*$D26/DayBasis)) | H26: =IF(OR($A26="",$F26=""),"",$C26/(1+$F26*$D26/DayBasis)) | I26: =IF($A26="","",'02_Buyers'!$AU13) | J26: =IF($A26="","",'02_Buyers'!$W13) | K26: =IF(OR($A26="",$I26=""),"",IF(OR(AND($I26="부보 유리",$J26="N"),AND($I26="무보험 유리",$J26="Y")),"검토",""))
... A164: =IF('02_Buyers'!$A151="","",'02_Buyers'!$A151) | B164: =IF($A164="","",'02_Buyers'!$AK151) | C164: =IF($A164="","",'02_Buyers'!$Z151) | D164: =IF($A164="","",'02_Buyers'!$V151) | E164: =IF($A164="","",'02_Buyers'!$AR151) | F164: =IF($A164="","",'02_Buyers'!$AS151) | G164: =IF(OR($A164="",$E164=""),"",$C164/(1+$E164*$D164/DayBasis)) | H164: =IF(OR($A164="",$F164=""),"",$C164/(1+$F164*$D164/DayBasis)) | I164: =IF($A164="","",'02_Buyers'!$AU151) | J164: =IF($A164="","",'02_Buyers'!$W151) | K164: =IF(OR($A164="",$I164=""),"",IF(OR(AND($I164="부보 유리",$J164="N"),AND($I164="무보험 유리",$J164="Y")),"검토",""))

Sheet 06_WeeklyGap
A1: 06_WeeklyGap — 8주 유동성 갭(USD천, G03 §2.8 Step 4)
A2: 누적현금(조치 전) = 기초현금 + Σ(기대입금 − 지출) · 조치 후 = 조치 전 + 매각 대금(매입 주부터) − 매각으로 빠진 기대입금 · 정답 체크: W5 최저 −150.5
A4: 주 | B4: 1 | C4: 2 | D4: 3 | E4: 4 | F4: 5 | G4: 6 | H4: 7 | I4: 8
A5: 기대입금 | B5: =SUMIFS('04_AR_Ledger'!$I$5:$I$11,'04_AR_Ledger'!$H$5:$H$11,B$4) | C5: =SUMIFS('04_AR_Ledger'!$I$5:$I$11,'04_AR_Ledger'!$H$5:$H$11,C$4) | D5: =SUMIFS('04_AR_Ledger'!$I$5:$I$11,'04_AR_Ledger'!$H$5:$H$11,D$4) | E5: =SUMIFS('04_AR_Ledger'!$I$5:$I$11,'04_AR_Ledger'!$H$5:$H$11,E$4) | F5: =SUMIFS('04_AR_Ledger'!$I$5:$I$11,'04_AR_Ledger'!$H$5:$H$11,F$4) | G5: =SUMIFS('04_AR_Ledger'!$I$5:$I$11,'04_AR_Ledger'!$H$5:$H$11,G$4) | H5: =SUMIFS('04_AR_Ledger'!$I$5:$I$11,'04_AR_Ledger'!$H$5:$H$11,H$4) | I5: =SUMIFS('04_AR_Ledger'!$I$5:$I$11,'04_AR_Ledger'!$H$5:$H$11,I$4)
A6: 지출 | B6: 70 | C6: 70 | D6: 70 | E6: 170 | F6: 70 | G6: 70 | H6: 70 | I6: 70
A7: 순현금 | B7: =B5-B6 | C7: =C5-C6 | D7: =D5-D6 | E7: =E5-E6 | F7: =F5-F6 | G7: =G5-G6 | H7: =H5-H6 | I7: =I5-I6
A8: 누적현금(조치 전) | B8: =Cash0+B7 | C8: =B8+C7 | D8: =C8+D7 | E8: =D8+E7 | F8: =E8+F7 | G8: =F8+G7 | H8: =G8+H7 | I8: =H8+I7
A9: 매각 대금(07) | B9: =IF(B$4>=SaleWeek,SUMPRODUCT('07_Solver'!$H$6:$H$12,'04_AR_Ledger'!$C$5:$C$11,1-'04_AR_Ledger'!$L$5:$L$11),0) | C9: =IF(C$4>=SaleWeek,SUMPRODUCT('07_Solver'!$H$6:$H$12,'04_AR_Ledger'!$C$5:$C$11,1-'04_AR_Ledger'!$L$5:$L$11),0) | D9: =IF(D$4>=SaleWeek,SUMPRODUCT('07_Solver'!$H$6:$H$12,'04_AR_Ledger'!$C$5:$C$11,1-'04_AR_Ledger'!$L$5:$L$11),0) | E9: =IF(E$4>=SaleWeek,SUMPRODUCT('07_Solver'!$H$6:$H$12,'04_AR_Ledger'!$C$5:$C$11,1-'04_AR_Ledger'!$L$5:$L$11),0) | F9: =IF(F$4>=SaleWeek,SUMPRODUCT('07_Solver'!$H$6:$H$12,'04_AR_Ledger'!$C$5:$C$11,1-'04_AR_Ledger'!$L$5:$L$11),0) | G9: =IF(G$4>=SaleWeek,SUMPRODUCT('07_Solver'!$H$6:$H$12,'04_AR_Ledger'!$C$5:$C$11,1-'04_AR_Ledger'!$L$5:$L$11),0) | H9: =IF(H$4>=SaleWeek,SUMPRODUCT('07_Solver'!$H$6:$H$12,'04_AR_Ledger'!$C$5:$C$11,1-'04_AR_Ledger'!$L$5:$L$11),0) | I9: =IF(I$4>=SaleWeek,SUMPRODUCT('07_Solver'!$H$6:$H$12,'04_AR_Ledger'!$C$5:$C$11,1-'04_AR_Ledger'!$L$5:$L$11),0)
A10: 빠진 기대입금(07) | B10: =SUMPRODUCT('07_Solver'!$H$6:$H$12,'04_AR_Ledger'!$C$5:$C$11,1-'04_AR_Ledger'!$G$5:$G$11,('04_AR_Ledger'!$H$5:$H$11<=B$4)*1) | C10: =SUMPRODUCT('07_Solver'!$H$6:$H$12,'04_AR_Ledger'!$C$5:$C$11,1-'04_AR_Ledger'!$G$5:$G$11,('04_AR_Ledger'!$H$5:$H$11<=C$4)*1) | D10: =SUMPRODUCT('07_Solver'!$H$6:$H$12,'04_AR_Ledger'!$C$5:$C$11,1-'04_AR_Ledger'!$G$5:$G$11,('04_AR_Ledger'!$H$5:$H$11<=D$4)*1) | E10: =SUMPRODUCT('07_Solver'!$H$6:$H$12,'04_AR_Ledger'!$C$5:$C$11,1-'04_AR_Ledger'!$G$5:$G$11,('04_AR_Ledger'!$H$5:$H$11<=E$4)*1) | F10: =SUMPRODUCT('07_Solver'!$H$6:$H$12,'04_AR_Ledger'!$C$5:$C$11,1-'04_AR_Ledger'!$G$5:$G$11,('04_AR_Ledger'!$H$5:$H$11<=F$4)*1) | G10: =SUMPRODUCT('07_Solver'!$H$6:$H$12,'04_AR_Ledger'!$C$5:$C$11,1-'04_AR_Ledger'!$G$5:$G$11,('04_AR_Ledger'!$H$5:$H$11<=G$4)*1) | H10: =SUMPRODUCT('07_Solver'!$H$6:$H$12,'04_AR_Ledger'!$C$5:$C$11,1-'04_AR_Ledger'!$G$5:$G$11,('04_AR_Ledger'!$H$5:$H$11<=H$4)*1) | I10: =SUMPRODUCT('07_Solver'!$H$6:$H$12,'04_AR_Ledger'!$C$5:$C$11,1-'04_AR_Ledger'!$G$5:$G$11,('04_AR_Ledger'!$H$5:$H$11<=I$4)*1)
A11: 누적현금(조치 후) | B11: =B8+B9-B10 | C11: =C8+C9-C10 | D11: =D8+D9-D10 | E11: =E8+E9-E10 | F11: =F8+F9-F10 | G11: =G8+G9-G10 | H11: =H8+H9-H10 | I11: =I8+I9-I10
A13: 최저 누적현금(조치 전) | B13: =MIN(B8:I8) | C13: -150.5 | D13: =IF(ABS(B13-C13)<0.05,"✔ G03 일치","✘")
A14: 최저 누적현금(조치 후) | B14: =MIN(B11:I11)
A15: 호라이즌 밖 기대입금(W9·W10) | B15: =SUMIFS('04_AR_Ledger'!$I$5:$I$11,'04_AR_Ledger'!$H$5:$H$11,">8")

Sheet 07_Solver
A1: 07_Solver — 최소비용 매각(🔵 해 찾기 모델 저장됨: 목표 $D$15 최소 · 변수 $H$6:$H$12 · 제약 2줄)
A2: 결정변수 x = 매각 비율(0~1). 비용 = Σ x × 금액 × 단위비용(r 부보 × 잔존일 ÷ 360). 제약: x ≤ 상한(매각 가능 × C급 허용), 06 누적현금(조치 후) ≥ 0
A3: 정답 체크(G03): 최소비용 약 USD 886 — W3에 R3 19.2 · R5 99.8 · R7 32.4천 매입 의뢰. 'C급 허용' = 0으로 바꿔도 같은 해(C급 R4는 원래 안 판다)
A4: C급 매각 허용(1/0) | B4: 1
A5: 채권ID | B5: 등급 | C5: 금액(USD천) | D5: 단위비용 | E5: 매각 가능 | F5: C급 허용 | G5: x 상한 | H5: x(결정변수) | I5: 매각액(USD천) | J5: 비용(USD천)
A6: ='04_AR_Ledger'!A5 | B6: ='04_AR_Ledger'!B5 | C6: ='04_AR_Ledger'!C5 | D6: ='04_AR_Ledger'!L5 | E6: ='04_AR_Ledger'!M5 | F6: =IF(B6="C",$B$4,1) | G6: =E6*F6 | H6: 0 | I6: =H6*C6 | J6: =I6*D6
A7: ='04_AR_Ledger'!A6 | B7: ='04_AR_Ledger'!B6 | C7: ='04_AR_Ledger'!C6 | D7: ='04_AR_Ledger'!L6 | E7: ='04_AR_Ledger'!M6 | F7: =IF(B7="C",$B$4,1) | G7: =E7*F7 | H7: 0 | I7: =H7*C7 | J7: =I7*D7
A8: ='04_AR_Ledger'!A7 | B8: ='04_AR_Ledger'!B7 | C8: ='04_AR_Ledger'!C7 | D8: ='04_AR_Ledger'!L7 | E8: ='04_AR_Ledger'!M7 | F8: =IF(B8="C",$B$4,1) | G8: =E8*F8 | H8: 0 | I8: =H8*C8 | J8: =I8*D8
A9: ='04_AR_Ledger'!A8 | B9: ='04_AR_Ledger'!B8 | C9: ='04_AR_Ledger'!C8 | D9: ='04_AR_Ledger'!L8 | E9: ='04_AR_Ledger'!M8 | F9: =IF(B9="C",$B$4,1) | G9: =E9*F9 | H9: 0 | I9: =H9*C9 | J9: =I9*D9
A10: ='04_AR_Ledger'!A9 | B10: ='04_AR_Ledger'!B9 | C10: ='04_AR_Ledger'!C9 | D10: ='04_AR_Ledger'!L9 | E10: ='04_AR_Ledger'!M9 | F10: =IF(B10="C",$B$4,1) | G10: =E10*F10 | H10: 0 | I10: =H10*C10 | J10: =I10*D10
A11: ='04_AR_Ledger'!A10 | B11: ='04_AR_Ledger'!B10 | C11: ='04_AR_Ledger'!C10 | D11: ='04_AR_Ledger'!L10 | E11: ='04_AR_Ledger'!M10 | F11: =IF(B11="C",$B$4,1) | G11: =E11*F11 | H11: 0 | I11: =H11*C11 | J11: =I11*D11
A12: ='04_AR_Ledger'!A11 | B12: ='04_AR_Ledger'!B11 | C12: ='04_AR_Ledger'!C11 | D12: ='04_AR_Ledger'!L11 | E12: ='04_AR_Ledger'!M11 | F12: =IF(B12="C",$B$4,1) | G12: =E12*F12 | H12: 0 | I12: =H12*C12 | J12: =I12*D12
A14: 제약: 누적현금(조치 후) W1~W8 ≥ 0 | B14: ='06_WeeklyGap'!B11 | C14: ='06_WeeklyGap'!C11 | D14: ='06_WeeklyGap'!D11 | E14: ='06_WeeklyGap'!E11 | F14: ='06_WeeklyGap'!F11 | G14: ='06_WeeklyGap'!G11 | H14: ='06_WeeklyGap'!H11 | I14: ='06_WeeklyGap'!I11
A15: 총 할인비용(USD천) — 목표(최소) | D15: =SUMPRODUCT(H6:H12,C6:C12,D6:D12)
A16: 총 할인비용(USD) | D16: =D15*1000 | E16: 886 | F16: =IF(ABS(D16-E16)<1,"✔ G03 일치(약 886)","해 찾기 실행 전/확인")
A18: 해 찾기 입력표
A19: 목표 설정: $D$15 → 최소값
A20: 변수 셀 변경: $H$6:$H$12
A21: 제약 1: $H$6:$H$12 <= $G$6:$G$12
A22: 제약 2: $B$14:$I$14 >= 0
A23: '제한되지 않는 변수를 음이 아닌 수로' ✔ · 해법: 단순 LP

Sheet 08_Sensitivity
A1: 08_Sensitivity — 할인율·매각비용 민감도(현재 07 매각안 기준)
A2: 케이스별 r 부보 = (TSOFR3M + Δ) + Spread_g + Prem_g × 365 ÷ Tenor + MIN(1, PD_g × 배수) × LGD × (1 − Cov)
A3: 매각 조합은 07의 x 그대로(케이스마다 해 찾기를 다시 돌리면 조합이 바뀔 수 있다 — 🔵 실험). PD 배수는 할인율에만 반영(기대입금은 기준 PD)
A4: 등급별 x·금액·잔존일 합(07)
A5: 등급 | B5: Σ x·금액·잔존일
A6: S | B6: =SUMPRODUCT(('04_AR_Ledger'!$B$5:$B$11="S")*'07_Solver'!$H$6:$H$12*'04_AR_Ledger'!$C$5:$C$11*'04_AR_Ledger'!$K$5:$K$11)
A7: A | B7: =SUMPRODUCT(('04_AR_Ledger'!$B$5:$B$11="A")*'07_Solver'!$H$6:$H$12*'04_AR_Ledger'!$C$5:$C$11*'04_AR_Ledger'!$K$5:$K$11)
A8: B | B8: =SUMPRODUCT(('04_AR_Ledger'!$B$5:$B$11="B")*'07_Solver'!$H$6:$H$12*'04_AR_Ledger'!$C$5:$C$11*'04_AR_Ledger'!$K$5:$K$11)
A9: C | B9: =SUMPRODUCT(('04_AR_Ledger'!$B$5:$B$11="C")*'07_Solver'!$H$6:$H$12*'04_AR_Ledger'!$C$5:$C$11*'04_AR_Ledger'!$K$5:$K$11)
A11: 케이스 | B11: ΔTSOFR | C11: PD 배수 | D11: LGD | E11: r 부보 S | F11: r 부보 A | G11: r 부보 B | H11: r 부보 C | I11: 매각비용(USD) | J11: 기준 대비(USD) | K11: W5 누적현금(조치 후)
A12: 기준 | B12: 0 | C12: 1 | D12: =LGD | E12: =TSOFR3M+$B12+Spread_S+Prem_S*365/Tenor+MIN(1,PD_S*$C12)*$D12*(1-Cov) | F12: =TSOFR3M+$B12+Spread_A+Prem_A*365/Tenor+MIN(1,PD_A*$C12)*$D12*(1-Cov) | G12: =TSOFR3M+$B12+Spread_B+Prem_B*365/Tenor+MIN(1,PD_B*$C12)*$D12*(1-Cov) | H12: =TSOFR3M+$B12+Spread_C+Prem_C*365/Tenor+MIN(1,PD_C*$C12)*$D12*(1-Cov) | I12: =($E12*$B$6+$F12*$B$7+$G12*$B$8+$H12*$B$9)/DayBasis*1000 | J12: =I12-$I$12 | K12: ='06_WeeklyGap'!$F$11+($I$12-I12)/1000
A13: TSOFR +100bp | B13: 0.01 | C13: 1 | D13: =LGD | E13: =TSOFR3M+$B13+Spread_S+Prem_S*365/Tenor+MIN(1,PD_S*$C13)*$D13*(1-Cov) | F13: =TSOFR3M+$B13+Spread_A+Prem_A*365/Tenor+MIN(1,PD_A*$C13)*$D13*(1-Cov) | G13: =TSOFR3M+$B13+Spread_B+Prem_B*365/Tenor+MIN(1,PD_B*$C13)*$D13*(1-Cov) | H13: =TSOFR3M+$B13+Spread_C+Prem_C*365/Tenor+MIN(1,PD_C*$C13)*$D13*(1-Cov) | I13: =($E13*$B$6+$F13*$B$7+$G13*$B$8+$H13*$B$9)/DayBasis*1000 | J13: =I13-$I$12 | K13: ='06_WeeklyGap'!$F$11+($I$12-I13)/1000
A14: TSOFR −100bp | B14: -0.01 | C14: 1 | D14: =LGD | E14: =TSOFR3M+$B14+Spread_S+Prem_S*365/Tenor+MIN(1,PD_S*$C14)*$D14*(1-Cov) | F14: =TSOFR3M+$B14+Spread_A+Prem_A*365/Tenor+MIN(1,PD_A*$C14)*$D14*(1-Cov) | G14: =TSOFR3M+$B14+Spread_B+Prem_B*365/Tenor+MIN(1,PD_B*$C14)*$D14*(1-Cov) | H14: =TSOFR3M+$B14+Spread_C+Prem_C*365/Tenor+MIN(1,PD_C*$C14)*$D14*(1-Cov) | I14: =($E14*$B$6+$F14*$B$7+$G14*$B$8+$H14*$B$9)/DayBasis*1000 | J14: =I14-$I$12 | K14: ='06_WeeklyGap'!$F$11+($I$12-I14)/1000
A15: PD × 2 | B15: 0 | C15: 2 | D15: =LGD | E15: =TSOFR3M+$B15+Spread_S+Prem_S*365/Tenor+MIN(1,PD_S*$C15)*$D15*(1-Cov) | F15: =TSOFR3M+$B15+Spread_A+Prem_A*365/Tenor+MIN(1,PD_A*$C15)*$D15*(1-Cov) | G15: =TSOFR3M+$B15+Spread_B+Prem_B*365/Tenor+MIN(1,PD_B*$C15)*$D15*(1-Cov) | H15: =TSOFR3M+$B15+Spread_C+Prem_C*365/Tenor+MIN(1,PD_C*$C15)*$D15*(1-Cov) | I15: =($E15*$B$6+$F15*$B$7+$G15*$B$8+$H15*$B$9)/DayBasis*1000 | J15: =I15-$I$12 | K15: ='06_WeeklyGap'!$F$11+($I$12-I15)/1000
A16: LGD 40% | B16: 0 | C16: 1 | D16: 0.4 | E16: =TSOFR3M+$B16+Spread_S+Prem_S*365/Tenor+MIN(1,PD_S*$C16)*$D16*(1-Cov) | F16: =TSOFR3M+$B16+Spread_A+Prem_A*365/Tenor+MIN(1,PD_A*$C16)*$D16*(1-Cov) | G16: =TSOFR3M+$B16+Spread_B+Prem_B*365/Tenor+MIN(1,PD_B*$C16)*$D16*(1-Cov) | H16: =TSOFR3M+$B16+Spread_C+Prem_C*365/Tenor+MIN(1,PD_C*$C16)*$D16*(1-Cov) | I16: =($E16*$B$6+$F16*$B$7+$G16*$B$8+$H16*$B$9)/DayBasis*1000 | J16: =I16-$I$12 | K16: ='06_WeeklyGap'!$F$11+($I$12-I16)/1000
A17: LGD 80% | B17: 0 | C17: 1 | D17: 0.8 | E17: =TSOFR3M+$B17+Spread_S+Prem_S*365/Tenor+MIN(1,PD_S*$C17)*$D17*(1-Cov) | F17: =TSOFR3M+$B17+Spread_A+Prem_A*365/Tenor+MIN(1,PD_A*$C17)*$D17*(1-Cov) | G17: =TSOFR3M+$B17+Spread_B+Prem_B*365/Tenor+MIN(1,PD_B*$C17)*$D17*(1-Cov) | H17: =TSOFR3M+$B17+Spread_C+Prem_C*365/Tenor+MIN(1,PD_C*$C17)*$D17*(1-Cov) | I17: =($E17*$B$6+$F17*$B$7+$G17*$B$8+$H17*$B$9)/DayBasis*1000 | J17: =I17-$I$12 | K17: ='06_WeeklyGap'!$F$11+($I$12-I17)/1000

Sheet 09_Chart
A1: 09_Chart — 누적현금(06) · 할인율 구성(03) · 등급별 한도(10)

Sheet 10_LimitLP
A1: 10_LimitLP — 바이어별 신용한도 배분 LP(해 찾기: 단순 LP · 모델 저장됨)
A2: 목적함수 Obj(최대화) | C2: =SUMPRODUCT(coef,L) | D2: ← 해 찾기 '목표 설정'
T3: 제약(해 찾기 입력표 ①②④ · ③은 아래 국가 블록)
A4: buyer_id | B4: country | C4: 등급 | D4: UB 상한 | E4: LB 하한 | F4: L 한도(결정변수) | G4: coef | H4: elc | I4: 현행 한도 | J4: 변경(L−현행) | K4: 변경률 | L4: 승인 표시 | M4: 한도 대상 | N4: 전결권자 | O4: 전략 | P4: L_ref(PuLP 참고해) | Q4: L − L_ref | R4: 동점 그룹(같은 coef 수) | T4: 제약 | U4: LHS | V4: 관계 | W4: RHS | X4: 여유 | Y4: 걸림? | Z4: 잠재가격(민감도 보고서에서 입력) | AA4: PuLP 참고
A5: =IF('02_Buyers'!$A2="","",'02_Buyers'!$A2) | B5: =IF($A5="","",'02_Buyers'!$S2) | C5: =IF($A5="","",'02_Buyers'!$AK2) | D5: =IF($A5="",0,'02_Buyers'!$BB2) | E5: =IF($A5="",0,'02_Buyers'!$BC2) | F5: 0 | G5: =IF($A5="",0,'02_Buyers'!$BD2) | H5: =IF($A5="",0,'02_Buyers'!$BE2) | I5: =IF($A5="",0,'02_Buyers'!$AB2) | J5: =IF($A5="","",F5-I5) | K5: =IF(OR($A5="",I5<=0),"",J5/I5) | L5: =IF($A5="","",IF(M5="대상 아님","대상 아님(L/C·선수금)",IF(AND(I5>0,K5<=-0.3),"감액 30%↑ — 사람 승인 필요",IF(J5>0,"증액 — 전결권자 승인","유지·소폭 감액")))) | M5: =IF($A5="","",'02_Buyers'!$BA2) | N5: =IF(OR($A5="",M5="대상 아님"),"",IF(F5<=50000,"채권관리팀장",IF(F5<=200000,"영업본부장","대표이사"))) | O5: =IF($A5="","",'02_Buyers'!$AG2) | Q5: =IF(OR($A5="",P5=""),"",F5-P5) | R5: =IF(OR($A5="",D5<=0),"",COUNTIFS($G$5:$G$154,G5,$D$5:$D$154,">0")) | T5: ① 총허용익스포저 Σ L ≤ TotalCap | U5: =SUM(L) | V5: ≤ | W5: =ROUND(TotalCapShare*SUM(UB),-5) | X5: =W5-U5 | Y5: =IF(X5<=0.5,"걸림","")
