Workbook

Sheet 요약
A1: 2026년 9월말 미수금 현황 — 지역별 요약 (단위: 천원)
A4: 지역 | B4: 건수 | C4: 원화(천원) | D4: 비고
A5: 아시아 | B5: =COUNTIF('아시아'!E5:E177,"INV*") -> 160 | C5: ='아시아'!H177 -> 5322816 | D5: 각 시트 합계 줄 기준
A6: 유럽·미주 | B6: =COUNTIF('유럽·미주'!E5:E122,"INV*") -> 109 | C6: ='유럽·미주'!H122 -> 3916852 | D6: 각 시트 합계 줄 기준
A7: 중동·아프리카 | B7: =COUNTIF('중동·아프리카'!E5:E42,"INV*") -> 33 | C7: ='중동·아프리카'!H42 -> 850645 | D7: 각 시트 합계 줄 기준
A8: 합계 | B8: =SUM(B5:B7) -> 302 | C8: =SUM(C5:C7) -> 10090313
A10: ※ 기준일 2026-09-30 · 영업팀 취합본(시트별 담당자가 직접 입력)

Sheet 아시아
A1: 2026년 9월말 미수금 현황 (단위: 천원)
A3: 담당 | B3: 바이어 | C3: 국가 | D3: 결제조건 | E3: 인보이스 번호 | F3: 선적일 | G3: 만기일 | H3: 금액 | K3: 메모
H4: 원화(천원) | I4: 외화 | J4: 통화
A5: 영업1팀 A | B5: Davura Kogyo Co., Ltd. | C5: Japan | D5: O/A 90 | E5: INV-2607-0164 | F5: 46230 | G5: 46320 | H5: 9897 | I5: 1104000 | J5: JPY
A6: 영업1팀 A | B6: Davura Kogyo Co., Ltd. | C6: Japan | D6: 사후송금 90일 | E6: INV-2608-0003 | F6: 26.8.1 | G6: 46325 | H6: 23896 | I6: 2647000 | J6: JPY
A7: 영업1팀 A | B7: Davura Kogyo Co., Ltd. | C7: Japan | D7: O/A 90일 | E7: INV-2608-0004 | F7: 46235 | G7: 46325 | H7: 16710 | I7: 1851000 | J7: JPY
A8: 영업1팀 A | B8: Davura Kogyo Co., Ltd. | C8: Japan | D8: O/A 90 | E8: INV-2608-0027 | F8: 46241 | G8: 11월 5일 | H8: 131614 | I8: 14706000 | J8: JPY
A9: 영업1팀 A | B9: Davura Kogyo Co., Ltd. | C9: Japan | D9: OA 90 DAYS | E9: INV-2608-0028 | F9: 8월 7일 | G9: 46331 | H9: 7,679 | I9: 858000 | J9: JPY
A10: 영업1팀 A | B10: Davura Kogyo Co., Ltd. | C10: Japan | D10: O/A 90일 | E10: INV-2608-0103 | F10: 46256 | G10: 46346 | H10: 12768 | I10: 1465000 | J10: JPY | K10: 9/25 통화, 10월 초 송금 약속
A11: 영업1팀 A | B11: Davura Kogyo Co., Ltd. | C11: Japan | D11: OA90days | E11: INV-2608-0112 | F11: 46257 | G11: 26.11.21 | H11: 40092 | I11: 4600000 | J11: JPY
A12: 영업1팀 A | B12: Davura Kogyo Co., Ltd. | C12: Japan | D12: OA 90 DAYS | E12: INV-2608-0118 | F12: 46258 | G12: 26.11.22 | H12: 7204 | I12: 829000 | J12: JPY
A13: 영업1팀 A | B13: Davura Kogyo Co., Ltd. | C13: Japan | D13: 사후송금 90일 | E13: INV-2609-0041 | F13: 46272 | G13: 46362 | H13: 28343 | I13: 3286000 | J13: JPY
A14: 영업1팀 A | B14: Davura Kogyo Co., Ltd. | C14: Japan | D14: OA90days | E14: INV-2609-0050 | F14: 9월 9일 | G14: 46364 | H14: 15100 | I14: 1730000 | J14: JPY | K14: 품질 클레임 협의 중
A15: 영업1팀 A | B15: Davura Kogyo Co., Ltd. | C15: Japan | D15: O/A 90 | E15: INV-2609-0069 | F15: 46278 | G15: 46368 | H15: 12931 | I15: 1483000 | J15: JPY
A16: 영업1팀 A | B16: Davura Kogyo Co., Ltd. | C16: Japan | D16: OA 90 DAYS | E16: INV-2609-0093 | F16: 46283 | G16: 12월 17일 | H16: 8246 | I16: 932000 | J16: JPY
A17: 영업1팀 A | B17: PT Sarida Sarana Industri | C17: Indonesia | D17: OA 30 DAYS | E17: INV-2606-0101 | F17: 46195 | G17: 46225 | H17: 7166 | I17: 4660 | J17: USD
A18: 영업1팀 A | B18: PT Sarida Sarana Industri | C18: Indonesia | D18: O/A 30 | E18: INV-2607-0035 | F18: 26.7.7 | G18: 46240 | H18: 2120 | I18: 1400 | J18: usd
A19: 영업1팀 A | B19: PT Sarida Sarana Industri | C19: Indonesia | D19: OA 30 DAYS | E19: INV-2609-0008 | F19: 46267 | G19: 46297 | H19: 14934 | I19: 10990 | J19: USD
A20: 영업1팀 A | B20: PT Sarida Sarana Industri | C20: Indonesia | D20: OA30days | E20: INV-2609-0054 | F20: 46275 | G20: 46305 | H20: 8101 | I20: 6020 | J20: US$
A21: 영업1팀 A | B21: PT Sarida Sarana Industri | C21: Indonesia | D21: OA30days | E21: INV-2609-0120 | F21: 46288 | G21: 46318 | H21: 25385 | I21: 18570 | J21: USD
A22: 영업1팀 A | B22: Pelant Automation Co., Ltd. | C22: Taiwan | D22: D/A 90 | E22: INV-2608-0002 | F22: 46235 | G22: 46325 | H22: 11035 | I22: 7680 | J22: USD
A23: 영업1팀 A 소계 | H23: =SUM(H5:H22) -> 375542
A25: 영업1팀 B | B25: Galost Automation Ltd. | C25: India | D25: DA90days | E25: INV-2607-0026 | F25: 26.7.5 | G25: 26.10.3 | H25: 20148 | I25: 13100 | J25: USD
A26: 영업1팀 B | B26: Galost Automation Ltd. | C26: India | D26: DA90days | E26: INV-2608-0030 | F26: 26.8.7 | G26: 26.11.5 | H26: 13705 | I26: 9720 | J26: USD
A27: 영업1팀 B | B27: Galost Automation Ltd. | C27: India | D27: OA30days | E27: INV-2608-0101 | F27: 46255 | G27: 26.9.20 | H27: 30346 | I27: 21910 | J27: USD
A28: 영업1팀 B | B28: Galost Automation Ltd. | C28: India | D28: D/A 90 | E28: INV-2609-0122 | F28: 26.9.23 | G28: 26.12.22 | H28: 5536 | I28: 4050 | J28: USD
A29: 영업1팀 B | B29: Nelera Kogyo Co., Ltd. | C29: Japan | D29: OA 60 DAYS | E29: INV-2608-0035 | F29: 26.8.8 | G29: 26.10.7 | H29: 8690 | I29: 971000 | J29: JPY
A30: 영업1팀 B | B30: Nelera Kogyo Co., Ltd. | C30: Japan | D30: O/A 60일 | E30: INV-2609-0139 | F30: 26.9.26 | G30: 26.11.25 | H30: 50435 | I30: 5844000 | J30: JPY
A31: 영업1팀 B | B31: Oroora Sangyo K.K. | C31: Japan | D31: OA60days | E31: INV-2608-0109 | F31: 46256 | G31: 26.10.21 | H31: 11932 | I31: 1369000 | J31: JPY
A32: 영업1팀 B | B32: Oroora Sangyo K.K. | C32: Japan | D32: O/A 60 | E32: INV-2609-0066 | F32: 26.9.12 | G32: 26.11.11 | H32: 3802 | I32: 436000 | J32: JPY
A33: 영업1팀 B | B33: PT Quineon Instrumen Nusantara | C33: Indonesia | D33: O/A 60일 | E33: INV-2608-0023 | F33: 26.8.5 | G33: 26.10.4 | H33: 11435 | I33: 8030 | J33: USD
A34: 영업1팀 B | B34: PT Quineon Instrumen Nusantara | C34: Indonesia | D34: OA60days | E34: INV-2609-0085 | F34: 26.9.15 | G34: 26.11.14 | H34: 4508 | I34: 3310 | J34: USD
A35: 영업1팀 B | B35: PT Quineon Instrumen Nusantara | C35: Indonesia | D35: O/A 60일 | E35: INV-2609-0134 | F35: 26.9.25 | G35: 26.11.24 | H35: 9726 | I35: 7170 | J35: USD
A36: 영업1팀 B | B36: PT Quineon Instrumen Nusantara | C36: Indonesia | D36: O/A 60일 | E36: INV-2609-0148 | F36: 26.9.27 | G36: 26.11.26 | H36: 1980505 | I36: 1460 | J36: USD
A37: 영업1팀 B | B37: Ralora Kogyo K.K. | C37: Japan | D37: OA90days | E37: INV-2607-0011 | F37: 26.7.3 | G37: 26.10.1 | H37: 11499 | I37: 1203000 | J37: JPY
A38: 영업1팀 B | B38: Ralora Kogyo K.K. | C38: Japan | D38: O/A 90일 | E38: INV-2607-0104 | F38: 26.7.18 | G38: 46311 | H38: 1962 | I38: 214000 | J38: JPY
A39: 영업1팀 B | B39: Rinella Distribution Co., Ltd. | C39: Taiwan | D39: 사후송금 60일 | E39: INV-2609-0109 | F39: 26.9.21 | G39: 26.11.20 | H39: 24472 | I39: 17800 | J39: USD
A40: 영업1팀 B | B40: Velova Keisoku K.K. | C40: Japan | D40: D/A 60 | E40: INV-2609-0027 | F40: 26.9.4 | G40: 26.11.3 | H40: 17760 | I40: 2059000 | J40: JPY
A41: 영업1팀 B | B41: Xiamen Rinant Engineering Co., Ltd. | C41: China | D41: 사후송금 60일 | E41: INV-2608-0033 | F41: 26.8.8 | G41: 26.10.7 | H41: 81348 | I41: 389300 | J41: CNY
A42: 영업1팀 B | B42: Xiamen Rinant Engineering Co., Ltd. | C42: China | D42: OA 60 DAYS | E42: INV-2608-0071 | F42: 26.8.16 | G42: 26.10.15 | H42: 7930 | I42: 37800 | J42: CNY
...

Sheet 유럽·미주
A1: 2026년 9월말 미수금 현황 (단위: 천원)
A3: 담당 | B3: 바이어 | C3: 국가 | D3: 결제조건 | E3: 인보이스 번호 | F3: 선적일 | G3: 만기일 | H3: 금액 | K3: 메모
H4: 원화(천원) | I4: 외화 | J4: 통화
A5: 영업2팀 A | B5: Calova Automation Inc. | C5: United States | D5: 사후송금 60일 | E5: INV-2609-0114 | F5: 46286 | G5: 46346 | H5: 10380 | I5: 7550 | J5: USD
A6: 영업2팀 A | B6: Camolin Instrumentación S.A. de C.V. | C6: Mexico | D6: O/A 60일 | E6: INV-2605-0106 | F6: 46161 | G6: 7월 18일 | H6: 47925 | I6: 31770 | J6: USD
A7: 영업2팀 A | B7: Camolin Instrumentación S.A. de C.V. | C7: Mexico | D7: 사후송금 60일 | E7: INV-2605-0135 | F7: 46167 | G7: 46227 | H7: 9741 | I7: 6420 | J7: US$
A8: 영업2팀 A | B8: Camolin Instrumentación S.A. de C.V. | C8: Mexico | D8: O/A 60 | E8: INV-2607-0093 | F8: 46220 | G8: 46280 | H8: 40855 | I8: 27430 | J8: USD
A9: 영업2팀 A | B9: Camolin Instrumentación S.A. de C.V. | C9: Mexico | D9: OA60days | E9: INV-2609-0037 | F9: 46271 | G9: 46331 | H9: 46131 | I9: 34260 | J9: USD
A10: 영업2팀 A | B10: Corari Industrie B.V. | C10: Netherlands | D10: OA 30 DAYS | E10: INV-2609-0014 | F10: 26.9.3 | G10: 46298 | H10: 3501 | I10: 2220 | J10: EUR
A11: 영업2팀 A | B11: Davix Industrietechnik AG | C11: Germany | D11: 사후송금 60일 | E11: INV-2608-0098 | F11: 46255 | G11: 46315 | H11: 29857 | I11: 18450 | J11: EUR
A12: 영업2팀 A | B12: Davix Industrietechnik AG | C12: Germany | D12: O/A 60일 | E12: INV-2609-0006 | F12: 46267 | G12: 46327 | H12: 11467 | I12: 7280 | J12: EUR | K12: 독촉 메일 9/20 발송, 회신 대기
A13: 영업2팀 A | B13: Davix Industrietechnik AG | C13: Germany | D13: OA60days | E13: INV-2609-0105 | F13: 46285 | G13: 46345 | H13: 72907 | I13: 45820 | J13: EUR
A14: 영업2팀 A | B14: Dorova Trading Corp. | C14: United States | D14: 사후송금 90일 | E14: INV-2608-0097 | F14: 46254 | G14: 46344 | H14: 17570 | I14: 12610 | J14: USD
A15: 영업2팀 A | B15: Dorova Trading Corp. | C15: USA | D15: 사후송금 90일 | E15: INV-2609-0084 | F15: 46280 | G15: 46370 | H15: 15539 | I15: 11410 | J15: USD
A16: 영업2팀 A | B16: Halano Handelsgesellschaft GmbH | C16: Germany | D16: O/A 30 | E16: INV-2609-0011 | F16: 46267 | G16: 46297 | H16: 13373 | I16: 8490 | J16: EUR
A17: 영업2팀 A | B17: Korolin Instruments LLC | C17: United States | D17: OA60days | E17: INV-2608-0049 | F17: 46245 | G17: 46305 | H17: 4606 | I17: 3260 | J17: USD
A18: 영업2팀 A | B18: Korolin Instruments LLC | C18: United States | D18: OA 60 DAYS | E18: INV-2608-0141 | F18: 46263 | G18: 46323 | H18: 54597 | I18: 39580 | J18: USD
A19: 영업2팀 A | B19: Korolin Instruments LLC | C19: United States | D19: 사후송금 60일 | E19: INV-2608-0145 | F19: 46264 | G19: 46324 | H19: 17836 | I19: 12930 | J19: USD
A20: 영업2팀 A | B20: Korolin Instruments LLC | C20: United States | D20: 사후송금 60일 | E20: INV-2609-0071 | F20: 46278 | G20: 46338 | H20: 16968 | I20: 12660 | J20: USD
A21: 영업2팀 A | B21: Korolin Instruments LLC | C21: United States | D21: 사후송금 60일 | E21: INV-2609-0152 | F21: 46293 | G21: 46353 | H21: 2618 | I21: 1930 | J21: USD
A22: 영업2팀 A | B22: Quinari Instruments Inc. | C22: United States | D22: OA 90 DAYS | E22: INV-2607-0156 | F22: 46229 | G22: 46319 | H22: 11204 | I22: 7670 | J22: USD
A23: 영업2팀 A | B23: Quinari Instruments Inc. | C23: United States | D23: 사후송금 90일 | E23: INV-2608-0093 | F23: 46254 | G23: 46344 | H23: 38958 | I23: 27960 | J23: USD
A24: 영업2팀 A | B24: Quinari Instruments Inc. | C24: United States | D24: OA90days | E24: INV-2608-0127 | F24: 46260 | G24: 46350 | H24: 20446 | I24: 14750 | J24: USD
A25: 영업2팀 A | B25: Ralora Kogyo K.K. | C25: Japan | D25: OA 90 DAYS | E25: INV-2607-0104 | F25: 46221 | G25: 26.10.16 | H25: 1962 | I25: 214000 | J25: JPY
A26: 영업2팀 A | B26: Sarant Ingeniería S.A. de C.V. | C26: Mexico | D26: 사후송금 60일 | E26: INV-2607-0165 | F26: 46230 | G26: 46290 | H26: 14954 | I26: 10190 | J26: USD
A27: 영업2팀 A | B27: Tarolin Przemysł Sp. z o.o. | C27: Poland | D27: OA 60 DAYS | E27: INV-2608-0151 | F27: 46265 | G27: 46325 | H27: 11731 | I27: 7380 | J27: EUR
A28: 영업2팀 A | B28: Tovera Messtechnik GmbH | C28: Germany | D28: O/A 60일 | E28: INV-2605-0022 | F28: 26.5.4 | G28: 46206 | H28: 10170 | I28: 5890 | J28: EUR
A29: 영업2팀 A | B29: Varant Handelsgesellschaft AG | C29: Germany | D29: D/A 90일 | E29: INV-2609-0039 | F29: 26.9.6 | G29: 46361 | H29: 12265 | I29: 7840 | J29: EUR
A30: 영업2팀 A | B30: Varant Handelsgesellschaft AG | C30: Germany | D30: D/A 90 | E30: INV-2609-0101 | F30: 26.9.19 | G30: 46374 | H30: 47,560 | I30: 29890 | J30: EUR
A31: 영업2팀 A 소계 | H31: =SUM(H5:H30) -> 537561
A33: 영업2팀 B | B33: Briella Manufacturing plc | C33: United Kingdom | D33: 사후송금 90일 | E33: INV-2607-0079 | F33: 7월 14일 | G33: 10월 12일 | H33: 7690 | I33: 5160 | J33: USD
A34: 영업2팀 B | B34: Briella Manufacturing plc | C34: United Kingdom | D34: OA 90 DAYS | E34: INV-2607-0148 | F34: 26.7.23 | G34: 10월 21일 | H34: 10398 | I34: 7050 | J34: USD
A35: 영업2팀 B | B35: Briella Manufacturing plc | C35: United Kingdom | D35: OA90days | E35: INV-2608-0006 | F35: 8월 1일 | G35: 10월 30일 | H35: 10561 | I35: 7350 | J35: USD
A36: 영업2팀 B | B36: Briella Manufacturing plc | C36: UK | D36: O/A 90일 | E36: INV-2608-0016 | F36: 8월 3일 | G36: 46327 | H36: 40712 | I36: 28460 | J36: USD
A37: 영업2팀 B | B37: Briella Manufacturing plc | C37: United Kingdom | D37: OA90days | E37: INV-2608-0075 | F37: 8월 16일 | G37: 11월 14일 | H37: 42146 | I37: 29800 | J37: USD
A38: 영업2팀 B | B38: Briella Manufacturing plc | C38: United Kingdom | D38: OA 90 DAYS | E38: INV-2609-0028 | F38: 9월 4일 | G38: 12월 3일 | H38: 6113 | I38: 4540 | J38: USD
A39: 영업2팀 B | B39: Halera Instruments Ltd | C39: UK | D39: O/A 60 | E39: INV-2609-0142 | F39: 9월 26일 | G39: 11월 25일 | H39: 2157 | I39: 1590 | J39: USD
A40: 영업2팀 B | B40: Korari Handel Sp. z o.o. | C40: Poland | D40: 사후송금 90일 | E40: INV-2608-0061 | F40: 8월 14일 | G40: 11월 12일 | H40: 5995 | I40: 3660 | J40: EUR
A41: 영업2팀 B | B41: Korari Handel Sp. z o.o. | C41: Poland | D41: 사후송금 90일 | E41: INV-2608-0095 | F41: 8월 20일 | G41: 26.11.18 | H41: 25565 | I41: 15710 | J41: EUR
A42: 영업2팀 B | B42: Korari Handel Sp. z o.o. | C42: Poland | D42: O/A 90일 | E42: INV-2608-0128 | F42: 8월 26일 | G42: 11월 24일 | H42: 1502 | I42: 930 | J42: EUR
...

Sheet 중동·아프리카
A1: 2026년 9월말 미수금 현황 (단위: 천원)
A3: 담당 | B3: 바이어 | C3: 국가 | D3: 결제조건 | E3: 인보이스 번호 | F3: 선적일 | G3: 만기일 | H3: 금액 | K3: 메모
H4: 원화(천원) | I4: 외화 | J4: 통화
A5: 영업3팀 A | B5: Bexura Industries S.A.E. | C5: Egypt | D5: OA30days | E5: INV-2608-0153 | F5: 26.8.31 | G5: 9월 30일 | H5: 2107 | I5: 1540 | J5: USD
A6: 영업3팀 A | B6: Bexura Industries S.A.E. | C6: Egypt | D6: O/A 30일 | E6: INV-2609-0154 | F6: 26.9.28 | G6: 26.10.28 | H6: 10323 | I6: 7610 | J6: USD
A7: 영업3팀 A | B7: Corida Trading LLC | C7: United Arab Emirates | D7: OA90days | E7: INV-2606-0043 | F7: 26.6.10 | G7: 26.9.8 | H7: 68367 | I7: 45000 | J7: USD
A8: 영업3팀 A | B8: Corida Trading LLC | C8: United Arab Emirates | D8: OA 90 DAYS | E8: INV-2607-0115 | F8: 26.7.20 | G8: 10월 18일 | H8: 103482 | I8: 70000 | J8: USD
A9: 영업3팀 A | B9: Corida Trading LLC | C9: United Arab Emirates | D9: OA 90 DAYS | E9: INV-2609-0031 | F9: 26.9.5 | G9: 26.12.4 | H9: 161581 | I9: 120000 | J9: USD
A10: 영업3팀 A | B10: Lumasta Engineering LLC | C10: United Arab Emirates | D10: D/A 90 | E10: INV-2605-0010 | F10: 46144 | G10: 26.7.31 | H10: 10075 | I10: 6820 | J10: USD
A11: 영업3팀 A | B11: Lumasta Engineering LLC | C11: United Arab Emirates | D11: D/A 90일 | E11: INV-2607-0048 | F11: 26.7.10 | G11: 26.10.8 | H11: 7235 | I11: 4820 | J11: USD | K11: 분할 입금 합의 — 10/10, 11/10
A12: 영업3팀 A | B12: Lumasta Engineering LLC | C12: United Arab Emirates | D12: D/A 90일 | E12: INV-2607-0049 | F12: 26.7.10 | G12: 26.10.8 | H12: 4908 | I12: 3270 | J12: USD
A13: 영업3팀 A | B13: Lumasta Engineering LLC | C13: United Arab Emirates | D13: D/A 90일 | E13: INV-2608-0043 | F13: 26.8.10 | G13: 26.11.8 | H13: 34446 | I13: 24300 | J13: USD
A14: 영업3팀 A | B14: Lumasta Engineering LLC | C14: United Arab Emirates | D14: D/A 90 | E14: INV-2609-0159 | F14: 26.9.30 | G14: 26.12.29 | H14: 21012 | I14: 15490 | J14: USD
A15: 영업3팀 A | B15: Marano Home & Lab Stores FZE | C15: United Arab Emirates | D15: DA60days | E15: INV-2607-0158 | F15: 26.7.26 | G15: 26.9.24 | H15: 17704 | I15: 12120 | J15: USD
A16: 영업3팀 A | B16: Marano Home & Lab Stores FZE | C16: United Arab Emirates | D16: DA60days | E16: INV-2608-0072 | F16: 26.8.16 | G16: 26.10.15 | H16: 7722 | I16: 5460 | J16: USD | K16: 분할 입금 합의 — 10/10, 11/10
A17: 영업3팀 A | B17: Marano Home & Lab Stores FZE | C17: United Arab Emirates | D17: OA90days | E17: INV-2609-0003 | F17: 26.9.1 | G17: 26.11.30 | H17: 16050 | I17: 11700 | J17: USD
A18: 영업3팀 A | B18: Marano Home & Lab Stores FZE | C18: United Arab Emirates | D18: D/A 60일 | E18: INV-2609-0072 | F18: 26.9.13 | G18: 26.11.12 | H18: 5388 | I18: 4020 | J18: USD
A19: 영업3팀 A | B19: Marano Home & Lab Stores FZE | C19: United Arab Emirates | D19: D/A 60일 | E19: INV-2609-0099 | F19: 26.9.19 | G19: 26.11.18 | H19: 50,022 | I19: 36040 | J19: USD
A20: 영업3팀 A | B20: Marano Home & Lab Stores FZE | C20: United Arab Emirates | D20: D/A 60일 | E20: INV-2609-0132 | F20: 26.9.25 | G20: 26.11.24 | H20: 17255 | I20: 12720 | J20: USD
A21: 영업3팀 A 소계 | H21: =SUM(H5:H20) -> 487655
A23: 영업3팀 B | B23: Bexova Industries Est. | C23: Saudi Arabia | D23: DA90days | E23: INV-2607-0143 | F23: 46226 | G23: 46316 | H23: 9321 | I23: 6320 | J23: USD
A24: 영업3팀 B | B24: Bexova Industries Est. | C24: Saudi Arabia | D24: DA90days | E24: INV-2609-0098 | F24: 46284 | G24: 46374 | H24: 11728 | I24: 8450 | J24: USD
A25: 영업3팀 B | B25: Camost Ticaret Ltd. Şti. | C25: Türkiye | D25: 사후송금 60일 | E25: INV-2607-0095 | F25: 7월 17일 | G25: 46280 | H25: 2741 | I25: 1840 | J25: USD
A26: 영업3팀 B | B26: Camost Ticaret Ltd. Şti. | C26: Turkey | D26: O/A 60일 | E26: INV-2608-0013 | F26: 46236 | G26: 46296 | H26: 20144 | I26: 14020 | J26: USD
A27: 영업3팀 B | B27: Camost Ticaret Ltd. Şti. | C27: Türkiye | D27: 사후송금 60일 | E27: INV-2608-0084 | F27: 46251 | G27: 46311 | H27: 11090 | I27: 7850 | J27: USD
A28: 영업3팀 B | B28: Camost Ticaret Ltd. Şti. | C28: Türkiye | D28: 사후송금 60일 | E28: INV-2608-0122 | F28: 46258 | G28: 46318 | H28: 1840 | I28: 1330 | J28: USD
A29: 영업3팀 B | B29: Davant Endüstriyel Ölçüm Ltd. Şti. | C29: Türkiye | D29: 사후송금 30일 | E29: INV-2608-0137 | F29: 46262 | G29: 46292 | H29: 15463 | I29: 11210 | J29: USD
A30: 영업3팀 B | B30: Davant Endüstriyel Ölçüm Ltd. Şti. | C30: Türkiye | D30: OA30days | E30: INV-2609-0103 | F30: 9월 20일 | G30: 46315 | H30: 29106 | I30: 20970 | J30: US$
A31: 영업3팀 B | B31: Davant Endüstriyel Ölçüm Ltd. Şti. | C31: Turkey | D31: O/A 30 | E31: INV-2609-0110 | F31: 46286 | G31: 46316 | H31: 2928 | I31: 2130 | J31: USD
A32: 영업3팀 B | B32: Davant Endüstriyel Ölçüm Ltd. Şti. | C32: Turkey | D32: O/A 30 | E32: INV-2609-0155 | F32: 46294 | G32: 46324 | H32: 11191 | I32: 8250 | J32: USD
A33: 영업3팀 B | B33: Morost Automation Ltd | C33: Nigeria | D33: L/C at sight | E33: INV-2609-0153 | F33: 46293 | G33: 46300 | H33: 1031 | I33: 760 | J33: USD
A34: 영업3팀 B | B34: Orunde State Water Board | C34: Nigeria | D34: OA 30 DAYS | E34: INV-2609-0058 | F34: 46276 | G34: 46306 | H34: 118027 | I34: 88060 | J34: USD
A35: 영업3팀 B | B35: Rovella Water Services FZE | C35: United Arab Emirates | D35: 사후송금 60일 | E35: INV-2608-0008 | F35: 46235 | G35: 46295 | H35: 75361 | I35: 52450 | J35: USD
A36: 영업3팀 B | B36: Rovella Water Services FZE | C36: United Arab Emirates | D36: 사후송금 60일 | E36: INV-2608-0057 | F36: 46246 | G36: 46306 | H36: 38,212 | I36: 26980 | J36: USD
A37: 영업3팀 B | B37: Rovella Water Services FZE | C37: United Arab Emirates | D37: OA 60 DAYS | E37: INV-2609-0040 | F37: 46271 | G37: 46331 | H37: 25557 | I37: 18980 | J37: USD
A38: 영업3팀 B | B38: Rovella Water Services FZE | C38: United Arab Emirates | D38: 사후송금 60일 | E38: INV-2609-0126 | F38: 46288 | G38: 46348 | H38: 7505 | I38: 5490 | J38: USD | K38: 10월말까지 일부 입금 약속
A39: 영업3팀 B | B39: Zarix Ticaret Ltd. Şti. | C39: Türkiye | D39: 사후송금 30일 | E39: INV-2609-0067 | F39: 46277 | G39: 46307 | H39: 19957 | I39: 14890 | J39: USD
A40: 영업3팀 B 소계 | H40: =SUM(H23:H39) -> 362990
A42: 합계 | H42: =H21+H40 -> 850645
